Workbook
Name LL_COR_BE_SEC_ACT: #REF!
Name LL_COR_BE_SEC_ACT: #REF!
Name LL_COR_BE_SEC_PLAN: #REF!
Name LL_COR_BE_SEC_PLAN: #REF!
Name LL_COR_BE_SEC_PREV: #REF!
Name LL_COR_BE_YTD_ACT: #REF!
Name LL_COR_BE_YTD_PLAN: #REF!
Name LL_COR_BE_YTD_PREV: #REF!
Name LL_COR_BR_SEC: #REF!
Name LL_COR_BR_SEC_PLAN: #REF!
Name LL_COR_BR_SEC_PREV: #REF!
Name LL_COR_BR_YTD: #REF!
Name LL_COR_BR_YTD_PLAN: #REF!
Name LL_COR_BR_YTD_PREV: #REF!
Name LL_COR_UA_SEC: #REF!
Name LL_COR_UA_SEC_PLAN: #REF!
Name LL_COR_UA_SEC_PREV: #REF!
Name LL_COR_UA_YTD: #REF!
Name LL_COR_UA_YTD_PLAN: #REF!
Name LL_COR_UA_YTD_PREV: #REF!
Name LL_FLE_BR_SEC: #REF!
Name LL_FLE_BR_SEC_PLAN: #REF!
Name LL_FLE_BR_SEC_PREV: #REF!
Name LL_FLE_BR_YTD: #REF!
Name LL_FLE_BR_YTD_PLAN: #REF!
Name LL_FLE_BR_YTD_PREV: #REF!
Name LL_FLE_UA_SEC: #REF!
Name LL_FLE_UA_SEC_PLAN: #REF!
Name LL_FLE_UA_SEC_PREV: #REF!
Name LL_FLE_UA_YTD: #REF!
Name LL_FLE_UA_YTD_PLAN: #REF!
Name LL_FLE_UA_YTD_PREV: #REF!
Name LL_IBNR_COR_BE_SEC_ACT: #REF!
Name LL_IBNR_COR_BE_SEC_PLAN: #REF!
Name LL_IBNR_COR_BE_SEC_PREV: #REF!
Name LL_IBNR_COR_BE_YTD_ACT: #REF!
Name LL_IBNR_COR_BE_YTD_PLAN: #REF!
Name LL_IBNR_COR_BE_YTD_PREV: #REF!
Name LL_IBNR_COR_BR_SEC: #REF!
Name LL_IBNR_COR_BR_SEC_PLAN: #REF!
Name LL_IBNR_COR_BR_SEC_PREV: #REF!
Name LL_IBNR_COR_BR_YTD: #REF!
Name LL_IBNR_COR_BR_YTD_PLAN: #REF!
Name LL_IBNR_COR_BR_YTD_PREV: #REF!
Name LL_IBNR_COR_UA_SEC: #REF!
Name LL_IBNR_COR_UA_SEC_PLAN: #REF!
Name LL_IBNR_COR_UA_SEC_PREV: #REF!
Name LL_IBNR_COR_UA_YTD: #REF!
Name LL_IBNR_COR_UA_YTD_PLAN: #REF!
Name LL_IBNR_COR_UA_YTD_PREV: #REF!
Name LL_IBNR_FLE_BR_SEC: #REF!
Name LL_IBNR_FLE_BR_SEC_PLAN: #REF!
Name LL_IBNR_FLE_BR_SEC_PREV: #REF!
Name LL_IBNR_FLE_BR_YTD: #REF!
Name LL_IBNR_FLE_BR_YTD_PLAN: #REF!
Name LL_IBNR_FLE_BR_YTD_PREV: #REF!
Name LL_IBNR_FLE_UA_SEC: #REF!
Name LL_IBNR_FLE_UA_SEC_PLAN: #REF!
Name LL_IBNR_FLE_UA_SEC_PREV: #REF!
Name LL_IBNR_FLE_UA_YTD: #REF!

Sheet Matrix Flash Report
B1: Financial results P&C per LoB - May 2024 - IFRS9/17 - excluding Quota Share AZSE and Holdings
B3: May 2024 -YTD | F3: The Netherlands | AL3: =B3 -> May 2024 -YTD | AP3: Belgium | BR3: Benelux
F4: Broker ex UWA | J4: Retail | N4: SME | R4: Midcorp | V4: MGA | Z4: Bancassurance | AD4: Other1 | AH4: Total | AP4: Broker ex UWA | AT4: Retail Broker | AX4: SME | BB4: Midcorp | BF4: UWA | BJ4: Other1 | BN4: Total | BR4: Total
F6: Actual | G6: Previous | H6: Plan | J6: Actual | K6: Previous | L6: Plan | N6: Actual | O6: Previous | P6: Plan | R6: Actual | S6: Previous | T6: Plan | V6: Actual | W6: Previous | X6: Plan | Z6: Actual | AA6: Previous | AB6: Plan | AD6: Actual | AE6: Previous | AF6: Plan | AH6: Actual | AI6: Previous | AJ6: Plan | AP6: Actual | AQ6: Previous | AR6: Plan | AT6: Actual | AU6: Previous | AV6: Plan | AX6: Actual | AY6: Previous | AZ6: Plan | BB6: Actual | BC6: Previous | BD6: Plan | BF6: Actual | BG6: Previous | BH6: Plan | BJ6: Actual | BK6: Previous | BL6: Plan | BN6: Actual | BO6: Previous | BP6: Plan | BR6: Actual | BS6: Previous | BT6: Plan
B9: Motor | D9: GWP | J9: =+[1]Retail!$C$29/1000 -> 1.5563908 | K9: =+[1]Retail!$C$30/1000 -> 1.9777291 | L9: =+[1]Retail!$C$31/1000 -> 0 | N9: =+[1]SME!$C$29/1000 -> 24.717281 | O9: =+[1]SME!$C$30/1000 -> 26.269872 | P9: =+[1]SME!$C$31/1000 -> 26.09868 | R9: =+[1]MidCorp!$C$29/1000 -> 88.71968 | S9: =+[1]MidCorp!$C$30/1000 -> 83.060786 | T9: =+[1]MidCorp!$C$31/1000 -> 86.51 | V9: =+[1]MGA!$C$29/1000 -> 34.64386 | W9: =+[1]MGA!$C$30/1000 -> 30.203168 | X9: =+[1]MGA!$C$31/1000 -> 33.01402 | Z9: =+[1]Bancassurance!$C$29/1000 -> 0.04775279 | AA9: =+[1]Bancassurance!$C$30/1000 -> 0 | AB9: =+[1]Bancassurance!$C$31/1000 -> 0 | AD9: =+[1]Specials!$C$29/1000 -> 0.22730861 | AE9: =+[1]Specials!$C$30/1000 -> 0.1526518 | AF9: =+[1]Specials!$C$31/1000 -> 0 | AH9: =+'[1]Total P&C'!$C$29/1000 -> 149.91227 | AI9: =+'[1]Total P&C'!$C$30/1000 -> 141.66421 | AJ9: =+'[1]Total P&C'!$C$31/1000 -> 145.6227 | AL9: Motor | AN9: GWP | AT9: =+[2]Retail!$C$29/1000 -> 13.385938 | AU9: =+[2]Retail!$C$30/1000 -> 13.556885 | AV9: =+[2]Retail!$C$31/1000 -> 15.051035 | AX9: =+[2]SME!$C$29/1000 -> 4.8422735 | AY9: =+[2]SME!$C$30/1000 -> 5.0260385 | AZ9: =+[2]SME!$C$31/1000 -> 5.1908403 | BB9: =+[2]MidCorp!$C$29/1000 -> 12.202893 | BC9: =+[2]MidCorp!$C$30/1000 -> 14.601782 | BD9: =+[2]MidCorp!$C$31/1000 -> 12.683401 | BJ9: =+[2]Specials!$C$29/1000 -> 0 | BK9: =+[2]Specials!$C$30/1000 -> 0 | BL9: =+[2]Specials!$C$31/1000 -> 0 | BN9: =+'[2]Total P&C'!$C$29/1000 -> 30.431104 | BO9: =+'[2]Total P&C'!$C$30/1000 -> 33.184705 | BP9: =+'[2]Total P&C'!$C$31/1000 -> 32.925277 | BR9: =+'[3]Total P&C'!$C$29/1000 -> 180.34338 | BS9: =+'[3]Total P&C'!$C$30/1000 -> 174.84891 | BT9: =+'[3]Total P&C'!$C$31/1000 -> 178.54798
D10: Insurance Service Revenue | J10: =+[1]Retail!$N$29/1000 -> 1.5321743 | K10: =+[1]Retail!$N$30/1000 -> 1.9449421 | L10: =+[1]Retail!$N$31/1000 -> 0 | N10: =+[1]SME!$N$29/1000 -> 15.290361 | O10: =+[1]SME!$N$30/1000 -> 16.305078 | P10: =+[1]SME!$N$31/1000 -> 16.131751 | R10: =+[1]MidCorp!$N$29/1000 -> 72.115851 | S10: =+[1]MidCorp!$N$30/1000 -> 65.510598 | T10: =+[1]MidCorp!$N$31/1000 -> 67.80625 | V10: =+[1]MGA!$N$29/1000 -> 28.361353 | W10: =+[1]MGA!$N$30/1000 -> 24.950295 | X10: =+[1]MGA!$N$31/1000 -> 30.189168 | Z10: =+[1]Bancassurance!$N$29/1000 -> 0.04395041 | AA10: =+[1]Bancassurance!$N$30/1000 -> 0 | AB10: =+[1]Bancassurance!$N$31/1000 -> 0 | AD10: =+[1]Specials!$N$29/1000 -> 0.0769724 | AE10: =+[1]Specials!$N$30/1000 -> 0.01878516 | AF10: =+[1]Specials!$N$31/1000 -> 0 | AH10: =+'[1]Total P&C'!$N$29/1000 -> 117.42066 | AI10: =+'[1]Total P&C'!$N$30/1000 -> 108.7297 | AJ10: =+'[1]Total P&C'!$N$31/1000 -> 114.12717 | AN10: Insurance Service Revenue | AT10: =+[2]Retail!$N$29/1000 -> 12.935799 | AU10: =+[2]Retail!$N$30/1000 -> 12.847086 | AV10: =+[2]Retail!$N$31/1000 -> 13.886397 | AX10: =+[2]SME!$N$29/1000 -> 4.0515994 | AY10: =+[2]SME!$N$30/1000 -> 4.1866977 | AZ10: =+[2]SME!$N$31/1000 -> 4.3052088 | BB10: =+[2]MidCorp!$N$29/1000 -> 8.0085514 | BC10: =+[2]MidCorp!$N$30/1000 -> 9.1735504 | BD10: =+[2]MidCorp!$N$31/1000 -> 7.9935288 | BJ10: =+[2]Specials!$N$29/1000 -> 0 | BK10: =+[2]Specials!$N$30/1000 -> 0 | BL10: =+[2]Specials!$N$31/1000 -> 0 | BN10: =+'[2]Total P&C'!$N$29/1000 -> 24.99595 | BO10: =+'[2]Total P&C'!$N$30/1000 -> 26.207334 | BP10: =+'[2]Total P&C'!$N$31/1000 -> 26.185134 | BR10: =+'[3]Total P&C'!$N$29/1000 -> 142.41661 | BS10: =+'[3]Total P&C'!$N$30/1000 -> 134.93703 | BT10: =+'[3]Total P&C'!$N$31/1000 -> 140.3123
D11: CoR | J11: =+J12+J17+J18+J19+J20 -> 0.99473412 | K11: =+K12+K17+K18+K19+K20 -> 0.7097323 | L11: =+L12+L17+L18+L19+L20 -> #DIV/0! | N11: =+N12+N17+N18+N19+N20 -> 0.90659368 | O11: =+O12+O17+O18+O19+O20 -> 1.0028137 | P11: =+P12+P17+P18+P19+P20 -> 0.91904973 | R11: =+R12+R17+R18+R19+R20 -> 0.98964589 | S11: =+S12+S17+S18+S19+S20 -> 0.92857687 | T11: =+T12+T17+T18+T19+T20 -> 0.96500341 | V11: =+V12+V17+V18+V19+V20 -> 0.9828153 | W11: =+W12+W17+W18+W19+W20 -> 0.92239117 | X11: =+X12+X17+X18+X19+X20 -> 0.96018478 | Z11: =+Z12+Z17+Z18+Z19+Z20 -> 0.15005275 | AA11: =+AA12+AA17+AA18+AA19+AA20 -> #DIV/0! | AB11: =+AB12+AB17+AB18+AB19+AB20 -> #DIV/0! | AD11: =+AD12+AD17+AD18+AD19+AD20 -> -7.2095916 | AE11: =+AE12+AE17+AE18+AE19+AE20 -> -30.095166 | AF11: =+AF12+AF17+AF18+AF19+AF20 -> #DIV/0! | AH11: =+AH12+AH17+AH18+AH19+AH20 -> 0.97155843 | AI11: =+AI12+AI17+AI18+AI19+AI20 -> 0.9292444 | AJ11: =+AJ12+AJ17+AJ18+AJ19+AJ20 -> 0.95579617 | AN11: CoR | AT11: =+AT12+AT17+AT18+AT19+AT20 -> 0.89813125 | AU11: =+AU12+AU17+AU18+AU19+AU20 -> 0.74489036 | AV11: =+AV12+AV17+AV18+AV19+AV20 -> 0.97887741 | AX11: =+AX12+AX17+AX18+AX19+AX20 -> 1.1016911 | AY11: =+AY12+AY17+AY18+AY19+AY20 -> 0.91191067 | AZ11: =+AZ12+AZ17+AZ18+AZ19+AZ20 -> 1.1263427 | BB11: =+BB12+BB17+BB18+BB19+BB20 -> 1.1423509 | BC11: =+BC12+BC17+BC18+BC19+BC20 -> 1.5009576 | BD11: =+BD12+BD17+BD18+BD19+BD20 -> 1.1733336 | BJ11: =+BJ12+BJ17+BJ18+BJ19+BJ20 -> #DIV/0! | BK11: =+BK12+BK17+BK18+BK19+BK20 -> #DIV/0! | BL11: =+BL12+BL17+BL18+BL19+BL20 -> #DIV/0! | BN11: =+BN12+BN17+BN18+BN19+BN20 -> 1.0093728 | BO11: =+BO12+BO17+BO18+BO19+BO20 -> 1.0362242 | BP11: =+BP12+BP17+BP18+BP19+BP20 -> 1.0624844 | BR11: =+BR12+BR17+BR18+BR19+BR20 -> 0.97819534 | BS11: =+BS12+BS17+BS18+BS19+BS20 -> 0.95002192 | BT11: =+BT12+BT17+BT18+BT19+BT20 -> 0.97570636
D12: L.R + ReR AY | J12: =+J13+J14+J15+J16 -> 0.14029228 | K12: =+K13+K14+K15+K16 -> 1.6124657 | L12: =+L13+L14+L15+L16 -> #DIV/0! | N12: =+N13+N14+N15+N16 -> 0.71160839 | O12: =+O13+O14+O15+O16 -> 0.57099348 | P12: =+P13+P14+P15+P16 -> 0.66376763 | R12: =+R13+R14+R15+R16 -> 0.76560473 | S12: =+S13+S14+S15+S16 -> 0.74944335 | T12: =+T13+T14+T15+T16 -> 0.77241344 | V12: =+V13+V14+V15+V16 -> 0.72387673 | W12: =+W13+W14+W15+W16 -> 0.7140264 | X12: =+X13+X14+X15+X16 -> 0.690213 | Z12: =+Z13+Z14+Z15+Z16 -> 0 | AA12: =+AA13+AA14+AA15+AA16 -> #DIV/0! | AB12: =+AB13+AB14+AB15+AB16 -> #DIV/0! | AD12: =+AD13+AD14+AD15+AD16 -> -5.5344513 | AE12: =+AE13+AE14+AE15+AE16 -> -22.502497 | AF12: =+AF13+AF14+AF15+AF16 -> #DIV/0! | AH12: =+AH13+AH14+AH15+AH16 -> 0.7359187 | AI12: =+AI13+AI14+AI15+AI16 -> 0.7259763 | AJ12: =+AJ13+AJ14+AJ15+AJ16 -> 0.73622729 | AN12: L.R + ReR AY | AT12: =+AT13+AT14+AT15+AT16 -> 0.7276934 | AU12: =+AU13+AU14+AU15+AU16 -> 0.81545182 | AV12: =+AV13+AV14+AV15+AV16 -> 0.65439232 | AX12: =+AX13+AX14+AX15+AX16 -> 0.86225949 | AY12: =+AY13+AY14+AY15+AY16 -> 0.61403742 | AZ12: =+AZ13+AZ14+AZ15+AZ16 -> 0.7212415 | BB12: =+BB13+BB14+BB15+BB16 -> 1.0676187 | BC12: =+BC13+BC14+BC15+BC16 -> 0.94336598 | BD12: =+BD13+BD14+BD15+BD16 -> 0.87513257 | BJ12: =+BJ13+BJ14+BJ15+BJ16 -> #DIV/0! | BK12: =+BK13+BK14+BK15+BK16 -> #DIV/0! | BL12: =+BL13+BL14+BL15+BL16 -> #DIV/0! | BN12: =+BN13+BN14+BN15+BN16 -> 0.85841525 | BO12: =+BO13+BO14+BO15+BO16 -> 0.82805004 | BP12: =+BP13+BP14+BP15+BP16 -> 0.73276859 | BR12: =+BR13+BR14+BR15+BR16 -> 0.75741843 | BS12: =+BS13+BS14+BS15+BS16 -> 0.74580096 | BT12: =+BT13+BT14+BT15+BT16 -> 0.73558183
D13: Attritional | J13: =-SUM([1]Retail!$O$29,[1]Retail!$R$29:$V$29,[1]Retail!$Y$29,[1]Retail!$AB$29,[1]Retail!$AU$29,[1]Retail!$AX$29,[1]Retail!$BA$29,[1]Retail!$BD$29)/1000/J10 -> 0.061285319 | K13: =-SUM([1]Retail!$O$30,[1]Retail!$R$30:$V$30,[1]Retail!$Y$30,[1]Retail!$AB$30,[1]Retail!$AU$30,[1]Retail!$AX$30,[1]Retail!$BA$30,[1]Retail!$BD$30)/1000/K10 -> 0.86744515 | L13: =-SUM([1]Retail!$O$31,[1]Retail!$R$31:$V$31,[1]Retail!$Y$31,[1]Retail!$AB$31,[1]Retail!$AU$31,[1]Retail!$AX$31,[1]Retail!$BA$31,[1]Retail!$BD$31)/1000/L10 -> #DIV/0! | N13: =-SUM([1]SME!$O$29,[1]SME!$R$29:$V$29,[1]SME!$Y$29,[1]SME!$AB$29,[1]SME!$AU$29,[1]SME!$AX$29,[1]SME!$BA$29,[1]SME!$BD$29)/1000/N10 -> 0.60795808 | O13: =-SUM([1]SME!$O$30,[1]SME!$R$30:$V$30,[1]SME!$Y$30,[1]SME!$AB$30,[1]SME!$AU$30,[1]SME!$AX$30,[1]SME!$BA$30,[1]SME!$BD$30)/1000/O10 -> 0.52107185 | P13: =-SUM([1]SME!$O$31,[1]SME!$R$31:$V$31,[1]SME!$Y$31,[1]SME!$AB$31,[1]SME!$AU$31,[1]SME!$AX$31,[1]SME!$BA$31,[1]SME!$BD$31)/1000/P10 -> 0.55247915 | R13: =-SUM([1]MidCorp!$O$29,[1]MidCorp!$R$29:$V$29,[1]MidCorp!$Y$29,[1]MidCorp!$AB$29,[1]MidCorp!$AU$29,[1]MidCorp!$AX$29,[1]MidCorp!$BA$29,[1]MidCorp!$BD$29)/1000/R10 -> 0.64185157 | S13: =-SUM([1]MidCorp!$O$30,[1]MidCorp!$R$30:$V$30,[1]MidCorp!$Y$30,[1]MidCorp!$AB$30,[1]MidCorp!$AU$30,[1]MidCorp!$AX$30,[1]MidCorp!$BA$30,[1]MidCorp!$BD$30)/1000/S10 -> 0.58438228 | T13: =-SUM([1]MidCorp!$O$31,[1]MidCorp!$R$31:$V$31,[1]MidCorp!$Y$31,[1]MidCorp!$AB$31,[1]MidCorp!$AU$31,[1]MidCorp!$AX$31,[1]MidCorp!$BA$31,[1]MidCorp!$BD$31)/1000/T10 -> 0.58771728 | V13: =-SUM([1]MGA!$O$29,[1]MGA!$R$29:$V$29,[1]MGA!$Y$29,[1]MGA!$AB$29,[1]MGA!$AU$29,[1]MGA!$AX$29,[1]MGA!$BA$29,[1]MGA!$BD$29)/1000/V10 -> 0.64391622 | W13: =-SUM([1]MGA!$O$30,[1]MGA!$R$30:$V$30,[1]MGA!$Y$30,[1]MGA!$AB$30,[1]MGA!$AU$30,[1]MGA!$AX$30,[1]MGA!$BA$30,[1]MGA!$BD$30)/1000/W10 -> 0.61171307 | X13: =-SUM([1]MGA!$O$31,[1]MGA!$R$31:$V$31,[1]MGA!$Y$31,[1]MGA!$AB$31,[1]MGA!$AU$31,[1]MGA!$AX$31,[1]MGA!$BA$31,[1]MGA!$BD$31)/1000/X10 -> 0.5825274 | Z13: =-SUM([1]Bancassurance!$O$29,[1]Bancassurance!$R$29:$V$29,[1]Bancassurance!$Y$29,[1]Bancassurance!$AB$29,[1]Bancassurance!$AU$29,[1]Bancassurance!$AX$29,[1]Bancassurance!$BA$29,[1]Bancassurance!$BD$29)/1000/Z10 -> 0 | AA13: =-SUM([1]Bancassurance!$O$30,[1]Bancassurance!$R$30:$V$30,[1]Bancassurance!$Y$30,[1]Bancassurance!$AB$30,[1]Bancassurance!$AU$30,[1]Bancassurance!$AX$30,[1]Bancassurance!$BA$30,[1]Bancassurance!$BD$30)/1000/AA10 -> #DIV/0! | AB13: =-SUM([1]Bancassurance!$O$31,[1]Bancassurance!$R$31:$V$31,[1]Bancassurance!$Y$31,[1]Bancassurance!$AB$31,[1]Bancassurance!$AU$31,[1]Bancassurance!$AX$31,[1]Bancassurance!$BA$31,[1]Bancassurance!$BD$31)/1000/AB10 -> #DIV/0! | AD13: =-SUM([1]Specials!$O$29,[1]Specials!$R$29:$V$29,[1]Specials!$Y$29,[1]Specials!$AB$29,[1]Specials!$AU$29,[1]Specials!$AX$29,[1]Specials!$BA$29,[1]Specials!$BD$29)/1000/AD10 -> 0 | AE13: =-SUM([1]Specials!$O$30,[1]Specials!$R$30:$V$30,[1]Specials!$Y$30,[1]Specials!$AB$30,[1]Specials!$AU$30,[1]Specials!$AX$30,[1]Specials!$BA$30,[1]Specials!$BD$30)/1000/AE10 -> 0.015278017 | AF13: =-SUM([1]Specials!$O$31,[1]Specials!$R$31:$V$31,[1]Specials!$Y$31,[1]Specials!$AB$31,[1]Specials!$AU$31,[1]Specials!$AX$31,[1]Specials!$BA$31,[1]Specials!$BD$31)/1000/AF10 -> #DIV/0! | AH13: =-SUM('[1]Total P&C'!$O$29,'[1]Total P&C'!$R$29:$V$29,'[1]Total P&C'!$Y$29,'[1]Total P&C'!$AB$29,'[1]Total P&C'!$AU$29,'[1]Total P&C'!$AX$29,'[1]Total P&C'!$BA$29,'[1]Total P&C'!$BD$29)/1000/AH10 -> 0.62970013 | AI13: =-SUM('[1]Total P&C'!$O$30,'[1]Total P&C'!$R$30:$V$30,'[1]Total P&C'!$Y$30,'[1]Total P&C'!$AB$30,'[1]Total P&C'!$AU$30,'[1]Total P&C'!$AX$30,'[1]Total P&C'!$BA$30,'[1]Total P&C'!$BD$30)/1000/AI10 -> 0.58612495 | AJ13: =-SUM('[1]Total P&C'!$O$31,'[1]Total P&C'!$R$31:$V$31,'[1]Total P&C'!$Y$31,'[1]Total P&C'!$AB$31,'[1]Total P&C'!$AU$31,'[1]Total P&C'!$AX$31,'[1]Total P&C'!$BA$31,'[1]Total P&C'!$BD$31)/1000/AJ10 -> 0.58227823 | AN13: Attritional | AT13: =-SUM([2]Retail!$O$29,[2]Retail!$R$29:$V$29,[2]Retail!$Y$29,[2]Retail!$AB$29,[2]Retail!$AU$29,[2]Retail!$AX$29,[2]Retail!$BA$29,[2]Retail!$BD$29)/1000/AT10 -> 0.65711188 | AU13: =-SUM([2]Retail!$O$30,[2]Retail!$R$30:$V$30,[2]Retail!$Y$30,[2]Retail!$AB$30,[2]Retail!$AU$30,[2]Retail!$AX$30,[2]Retail!$BA$30,[2]Retail!$BD$30)/1000/AU10 -> 0.69138911 | AV13: =-SUM([2]Retail!$O$31,[2]Retail!$R$31:$V$31,[2]Retail!$Y$31,[2]Retail!$AB$31,[2]Retail!$AU$31,[2]Retail!$AX$31,[2]Retail!$BA$31,[2]Retail!$BD$31)/1000/AV10 -> 0.56942389 | AX13: =-SUM([2]SME!$O$29,[2]SME!$R$29:$V$29,[2]SME!$Y$29,[2]SME!$AB$29,[2]SME!$AU$29,[2]SME!$AX$29,[2]SME!$BA$29,[2]SME!$BD$29)/1000/AX10 -> 0.7789166 | AY13: =-SUM([2]SME!$O$30,[2]SME!$R$30:$V$30,[2]SME!$Y$30,[2]SME!$AB$30,[2]SME!$AU$30,[2]SME!$AX$30,[2]SME!$BA$30,[2]SME!$BD$30)/1000/AY10 -> 0.55232458 | AZ13: =-SUM([2]SME!$O$31,[2]SME!$R$31:$V$31,[2]SME!$Y$31,[2]SME!$AB$31,[2]SME!$AU$31,[2]SME!$AX$31,[2]SME!$BA$31,[2]SME!$BD$31)/1000/AZ10 -> 0.63325558 | BB13: =-SUM([2]MidCorp!$O$29,[2]MidCorp!$R$29:$V$29,[2]MidCorp!$Y$29,[2]MidCorp!$AB$29,[2]MidCorp!$AU$29,[2]MidCorp!$AX$29,[2]MidCorp!$BA$29,[2]MidCorp!$BD$29)/1000/BB10 -> 0.91936447 | BC13: =-SUM([2]MidCorp!$O$30,[2]MidCorp!$R$30:$V$30,[2]MidCorp!$Y$30,[2]MidCorp!$AB$30,[2]MidCorp!$AU$30,[2]MidCorp!$AX$30,[2]MidCorp!$BA$30,[2]MidCorp!$BD$30)/1000/BC10 -> 0.84277604 | BD13: =-SUM([2]MidCorp!$O$31,[2]MidCorp!$R$31:$V$31,[2]MidCorp!$Y$31,[2]MidCorp!$AB$31,[2]MidCorp!$AU$31,[2]MidCorp!$AX$31,[2]MidCorp!$BA$31,[2]MidCorp!$BD$31)/1000/BD10 -> 0.66909069 | BJ13: =-SUM([2]Specials!$O$29,[2]Specials!$R$29:$V$29,[2]Specials!$Y$29,[2]Specials!$AB$29,[2]Specials!$AU$29,[2]Specials!$AX$29,[2]Specials!$BA$29,[2]Specials!$BD$29)/1000/BJ10 -> #DIV/0! | BK13: =-SUM([2]Specials!$O$30,[2]Specials!$R$30:$V$30,[2]Specials!$Y$30,[2]Specials!$AB$30,[2]Specials!$AU$30,[2]Specials!$AX$30,[2]Specials!$BA$30,[2]Specials!$BD$30)/1000/BK10 -> #DIV/0! | BL13: =-SUM([2]Specials!$O$31,[2]Specials!$R$31:$V$31,[2]Specials!$Y$31,[2]Specials!$AB$31,[2]Specials!$AU$31,[2]Specials!$AX$31,[2]Specials!$BA$31,[2]Specials!$BD$31)/1000/BL10 -> #DIV/0! | BN13: =-SUM('[2]Total P&C'!$O$29,'[2]Total P&C'!$R$29:$V$29,'[2]Total P&C'!$Y$29,'[2]Total P&C'!$AB$29,'[2]Total P&C'!$AU$29,'[2]Total P&C'!$AX$29,'[2]Total P&C'!$BA$29,'[2]Total P&C'!$BD$29)/1000/BN10 -> 0.76087938 | BO13: =-SUM('[2]Total P&C'!$O$30,'[2]Total P&C'!$R$30:$V$30,'[2]Total P&C'!$Y$30,'[2]Total P&C'!$AB$30,'[2]Total P&C'!$AU$30,'[2]Total P&C'!$AX$30,'[2]Total P&C'!$BA$30,'[2]Total P&C'!$BD$30)/1000/BO10 -> 0.72216426 | BP13: =-SUM('[2]Total P&C'!$O$31,'[2]Total P&C'!$R$31:$V$31,'[2]Total P&C'!$Y$31,'[2]Total P&C'!$AB$31,'[2]Total P&C'!$AU$31,'[2]Total P&C'!$AX$31,'[2]Total P&C'!$BA$31,'[2]Total P&C'!$BD$31)/1000/BP10 -> 0.61034398 | BR13: =-SUM('[3]Total P&C'!$O$29,'[3]Total P&C'!$R$29:$V$29,'[3]Total P&C'!$Y$29,'[3]Total P&C'!$AB$29,'[3]Total P&C'!$AU$29,'[3]Total P&C'!$AX$29,'[3]Total P&C'!$BA$29,'[3]Total P&C'!$BD$29)/1000/BR10 -> 0.65272377 | BS13: =-SUM('[3]Total P&C'!$O$30,'[3]Total P&C'!$R$30:$V$30,'[3]Total P&C'!$Y$30,'[3]Total P&C'!$AB$30,'[3]Total P&C'!$AU$30,'[3]Total P&C'!$AX$30,'[3]Total P&C'!$BA$30,'[3]Total P&C'!$BD$30)/1000/BS10 -> 0.61254636 | BT13: =-SUM('[3]Total P&C'!$O$31,'[3]Total P&C'!$R$31:$V$31,'[3]Total P&C'!$Y$31,'[3]Total P&C'!$AB$31,'[3]Total P&C'!$AU$31,'[3]Total P&C'!$AX$31,'[3]Total P&C'!$BA$31,'[3]Total P&C'!$BD$31)/1000/BT10 -> 0.58751587
D14: Nat Cat | J14: =-([1]Retail!$P$29+[1]Retail!$W$29+[1]Retail!$AV$29+[1]Retail!$AY$29)/1000/J10 -> 0 | K14: =-([1]Retail!$P$30+[1]Retail!$W$30+[1]Retail!$AV$30+[1]Retail!$AY$30)/1000/K10 -> 0 | L14: =-([1]Retail!$P$31+[1]Retail!$W$31+[1]Retail!$AV$31+[1]Retail!$AY$31)/1000/L10 -> #DIV/0! | N14: =-([1]SME!$P$29+[1]SME!$W$29+[1]SME!$AV$29+[1]SME!$AY$29)/1000/N10 -> 0 | O14: =-([1]SME!$P$30+[1]SME!$W$30+[1]SME!$AV$30+[1]SME!$AY$30)/1000/O10 -> 0 | P14: =-([1]SME!$P$31+[1]SME!$W$31+[1]SME!$AV$31+[1]SME!$AY$31)/1000/P10 -> 0.011985147 | R14: =-([1]MidCorp!$P$29+[1]MidCorp!$W$29+[1]MidCorp!$AV$29+[1]MidCorp!$AY$29)/1000/R10 -> 0 | S14: =-([1]MidCorp!$P$30+[1]MidCorp!$W$30+[1]MidCorp!$AV$30+[1]MidCorp!$AY$30)/1000/S10 -> 0 | T14: =-([1]MidCorp!$P$31+[1]MidCorp!$W$31+[1]MidCorp!$AV$31+[1]MidCorp!$AY$31)/1000/T10 -> 0.0095937088 | V14: =-([1]MGA!$P$29+[1]MGA!$W$29+[1]MGA!$AV$29+[1]MGA!$AY$29)/1000/V10 -> 8.9911084e-05 | W14: =-([1]MGA!$P$30+[1]MGA!$W$30+[1]MGA!$AV$30+[1]MGA!$AY$30)/1000/W10 -> 0 | X14: =-([1]MGA!$P$31+[1]MGA!$W$31+[1]MGA!$AV$31+[1]MGA!$AY$31)/1000/X10 -> 0.013029692 | Z14: =-([1]Bancassurance!$P$29+[1]Bancassurance!$W$29+[1]Bancassurance!$AV$29+[1]Bancassurance!$AY$29)/1000/Z10 -> 0 | AA14: =-([1]Bancassurance!$P$30+[1]Bancassurance!$W$30+[1]Bancassurance!$AV$30+[1]Bancassurance!$AY$30)/1000/AA10 -> #DIV/0! | AB14: =-([1]Bancassurance!$P$31+[1]Bancassurance!$W$31+[1]Bancassurance!$AV$31+[1]Bancassurance!$AY$31)/1000/AB10 -> #DIV/0! | AD14: =-([1]Specials!$P$29+[1]Specials!$W$29+[1]Specials!$AV$29+[1]Specials!$AY$29)/1000/AD10 -> 0 | AE14: =-([1]Specials!$P$30+[1]Specials!$W$30+[1]Specials!$AV$30+[1]Specials!$AY$30)/1000/AE10 -> 0 | AF14: =-([1]Specials!$P$31+[1]Specials!$W$31+[1]Specials!$AV$31+[1]Specials!$AY$31)/1000/AF10 -> #DIV/0! | AH14: =-('[1]Total P&C'!$P$29+'[1]Total P&C'!$W$29+'[1]Total P&C'!$AV$29+'[1]Total P&C'!$AY$29)/1000/AH10 -> 2.1716791e-05 | AI14: =-('[1]Total P&C'!$P$30+'[1]Total P&C'!$W$30+'[1]Total P&C'!$AV$30+'[1]Total P&C'!$AY$30)/1000/AI10 -> 0 | AJ14: =-('[1]Total P&C'!$P$31+'[1]Total P&C'!$W$31+'[1]Total P&C'!$AV$31+'[1]Total P&C'!$AY$31)/1000/AJ10 -> 0.01084063 | AN14: Nat Cat | AT14: =-([2]Retail!$P$29+[2]Retail!$W$29+[2]Retail!$AV$29+[2]Retail!$AY$29)/1000/AT10 -> 0.00064228579 | AU14: =-([2]Retail!$P$30+[2]Retail!$W$30+[2]Retail!$AV$30+[2]Retail!$AY$30)/1000/AU10 -> 0 | AV14: =-([2]Retail!$P$31+[2]Retail!$W$31+[2]Retail!$AV$31+[2]Retail!$AY$31)/1000/AV10 -> 0.0089138567 | AX14: =-([2]SME!$P$29+[2]SME!$W$29+[2]SME!$AV$29+[2]SME!$AY$29)/1000/AX10 -> 0.0029749042 | AY14: =-([2]SME!$P$30+[2]SME!$W$30+[2]SME!$AV$30+[2]SME!$AY$30)/1000/AY10 -> 0 | AZ14: =-([2]SME!$P$31+[2]SME!$W$31+[2]SME!$AV$31+[2]SME!$AY$31)/1000/AZ10 -> 0.012201748 | BB14: =-([2]MidCorp!$P$29+[2]MidCorp!$W$29+[2]MidCorp!$AV$29+[2]MidCorp!$AY$29)/1000/BB10 -> 0.00044565363 | BC14: =-([2]MidCorp!$P$30+[2]MidCorp!$W$30+[2]MidCorp!$AV$30+[2]MidCorp!$AY$30)/1000/BC10 -> 0 | BD14: =-([2]MidCorp!$P$31+[2]MidCorp!$W$31+[2]MidCorp!$AV$31+[2]MidCorp!$AY$31)/1000/BD10 -> 0.010818402 | BJ14: =-([2]Specials!$P$29+[2]Specials!$W$29+[2]Specials!$AV$29+[2]Specials!$AY$29)/1000/BJ10 -> #DIV/0! | BK14: =-([2]Specials!$P$30+[2]Specials!$W$30+[2]Specials!$AV$30+[2]Specials!$AY$30)/1000/BK10 -> #DIV/0! | BL14: =-([2]Specials!$P$31+[2]Specials!$W$31+[2]Specials!$AV$31+[2]Specials!$AY$31)/1000/BL10 -> #DIV/0! | BN14: =-('[2]Total P&C'!$P$29+'[2]Total P&C'!$W$29+'[2]Total P&C'!$AV$29+'[2]Total P&C'!$AY$29)/1000/BN10 -> 0.0009573807 | BO14: =-('[2]Total P&C'!$P$30+'[2]Total P&C'!$W$30+'[2]Total P&C'!$AV$30+'[2]Total P&C'!$AY$30)/1000/BO10 -> 0 | BP14: =-('[2]Total P&C'!$P$31+'[2]Total P&C'!$W$31+'[2]Total P&C'!$AV$31+'[2]Total P&C'!$AY$31)/1000/BP10 -> 0.010035833 | BR14: =-('[3]Total P&C'!$P$29+'[3]Total P&C'!$W$29+'[3]Total P&C'!$AV$29+'[3]Total P&C'!$AY$29)/1000/BR10 -> 0.00018593786 | BS14: =-('[3]Total P&C'!$P$30+'[3]Total P&C'!$W$30+'[3]Total P&C'!$AV$30+'[3]Total P&C'!$AY$30)/1000/BS10 -> 0 | BT14: =-('[3]Total P&C'!$P$31+'[3]Total P&C'!$W$31+'[3]Total P&C'!$AV$31+'[3]Total P&C'!$AY$31)/1000/BT10 -> 0.010690438
D15: Large Losses | J15: =-([1]Retail!$Q$29+[1]Retail!$X$29+[1]Retail!$AW$29+[1]Retail!$AZ$29)/1000/J10 -> 0 | K15: =-([1]Retail!$Q$30+[1]Retail!$X$30+[1]Retail!$AW$30+[1]Retail!$AZ$30)/1000/K10 -> 0.654453 | L15: =-([1]Retail!$Q$31+[1]Retail!$X$31+[1]Retail!$AW$31+[1]Retail!$AZ$31)/1000/L10 -> #DIV/0! | N15: =-([1]SME!$Q$29+[1]SME!$X$29-[1]SME!$AW$29+[1]SME!$AZ$29)/1000/N10 -> 0.079414014 | O15: =-([1]SME!$Q$30+[1]SME!$X$30+[1]SME!$AW$30+[1]SME!$AZ$30)/1000/O10 -> 0.025017484 | P15: =-([1]SME!$Q$31+[1]SME!$X$31+[1]SME!$AW$31+[1]SME!$AZ$31)/1000/P10 -> 0.07701123 | R15: =-([1]MidCorp!$Q$29+[1]MidCorp!$X$29+[1]MidCorp!$AW$29+[1]MidCorp!$AZ$29)/1000/R10 -> 0.098017172 | S15: =-([1]MidCorp!$Q$30+[1]MidCorp!$X$30+[1]MidCorp!$AW$30+[1]MidCorp!$AZ$30)/1000/S10 -> 0.0895594 | T15: =-([1]MidCorp!$Q$31+[1]MidCorp!$X$31+[1]MidCorp!$AW$31+[1]MidCorp!$AZ$31)/1000/T10 -> 0.083244052 | V15: =-([1]MGA!$Q$29+[1]MGA!$X$29+[1]MGA!$AW$29+[1]MGA!$AZ$29)/1000/V10 -> 0.063195476 | W15: =-([1]MGA!$Q$30+[1]MGA!$X$30+[1]MGA!$AW$30+[1]MGA!$AZ$30)/1000/W10 -> 0.081869222 | X15: =-([1]MGA!$Q$31+[1]MGA!$X$31+[1]MGA!$AW$31+[1]MGA!$AZ$31)/1000/X10 -> 0.068896058 | Z15: =-([1]Bancassurance!$Q$29+[1]Bancassurance!$X$29+[1]Bancassurance!$AW$29+[1]Bancassurance!$AZ$29)/1000/Z10 -> 0 | AA15: =-([1]Bancassurance!$Q$30+[1]Bancassurance!$X$30+[1]Bancassurance!$AW$30+[1]Bancassurance!$AZ$30)/1000/AA10 -> #DIV/0! | AB15: =-([1]Bancassurance!$Q$31+[1]Bancassurance!$X$31+[1]Bancassurance!$AW$31+[1]Bancassurance!$AZ$31)/1000/AB10 -> #DIV/0! | AD15: =-([1]Specials!$Q$29+[1]Specials!$X$29+[1]Specials!$AW$29+[1]Specials!$AZ$29)/1000/AD10 -> 0 | AE15: =-([1]Specials!$Q$30+[1]Specials!$X$30+[1]Specials!$AW$30+[1]Specials!$AZ$30)/1000/AE10 -> 0 | AF15: =-([1]Specials!$Q$31+[1]Specials!$X$31+[1]Specials!$AW$31+[1]Specials!$AZ$31)/1000/AF10 -> #DIV/0! | AH15: =-('[1]Total P&C'!$Q$29+'[1]Total P&C'!$X$29+'[1]Total P&C'!$AW$29+'[1]Total P&C'!$AZ$29)/1000/AH10 -> 0.085804063 | AI15: =-('[1]Total P&C'!$Q$30+'[1]Total P&C'!$X$30+'[1]Total P&C'!$AW$30+'[1]Total P&C'!$AZ$30)/1000/AI10 -> 0.088205306 | AJ15: =-('[1]Total P&C'!$Q$31+'[1]Total P&C'!$X$31+'[1]Total P&C'!$AW$31+'[1]Total P&C'!$AZ$31)/1000/AJ10 -> 0.078567687 | AN15: Large Losses | AT15: =-([2]Retail!$Q$29+[2]Retail!$X$29+[2]Retail!$AW$29+[2]Retail!$AZ$29)/1000/AT10 -> 0.050869014 | AU15: =-([2]Retail!$Q$30+[2]Retail!$X$30+[2]Retail!$AW$30+[2]Retail!$AZ$30)/1000/AU10 -> 0.066791024 | AV15: =-([2]Retail!$Q$31+[2]Retail!$X$31+[2]Retail!$AW$31+[2]Retail!$AZ$31)/1000/AV10 -> 0.04593048 | AX15: =-([2]SME!$Q$29+[2]SME!$X$29-[2]SME!$AW$29+[2]SME!$AZ$29)/1000/AX10 -> 0.065168147 | AY15: =-([2]SME!$Q$30+[2]SME!$X$30+[2]SME!$AW$30+[2]SME!$AZ$30)/1000/AY10 -> 0.041247306 | AZ15: =-([2]SME!$Q$31+[2]SME!$X$31+[2]SME!$AW$31+[2]SME!$AZ$31)/1000/AZ10 -> 0.059445083 | BB15: =-([2]MidCorp!$Q$29+[2]MidCorp!$X$29+[2]MidCorp!$AW$29+[2]MidCorp!$AZ$29)/1000/BB10 -> 0.068561243 | BC15: =-([2]MidCorp!$Q$30+[2]MidCorp!$X$30+[2]MidCorp!$AW$30+[2]MidCorp!$AZ$30)/1000/BC10 -> 0.035598213 | BD15: =-([2]MidCorp!$Q$31+[2]MidCorp!$X$31+[2]MidCorp!$AW$31+[2]MidCorp!$AZ$31)/1000/BD10 -> 0.076820009 | BJ15: =-([2]Specials!$Q$29+[2]Specials!$X$29+[2]Specials!$AW$29+[2]Specials!$AZ$29)/1000/BJ10 -> #DIV/0! | BK15: =-([2]Specials!$Q$30+[2]Specials!$X$30+[2]Specials!$AW$30+[2]Specials!$AZ$30)/1000/BK10 -> #DIV/0! | BL15: =-([2]Specials!$Q$31+[2]Specials!$X$31+[2]Specials!$AW$31+[2]Specials!$AZ$31)/1000/BL10 -> #DIV/0! | BN15: =-('[2]Total P&C'!$Q$29+'[2]Total P&C'!$X$29+'[2]Total P&C'!$AW$29+'[2]Total P&C'!$AZ$29)/1000/BN10 -> 0.058855247 | BO15: =-('[2]Total P&C'!$Q$30+'[2]Total P&C'!$X$30+'[2]Total P&C'!$AW$30+'[2]Total P&C'!$AZ$30)/1000/BO10 -> 0.051791686 | BP15: =-('[2]Total P&C'!$Q$31+'[2]Total P&C'!$X$31+'[2]Total P&C'!$AW$31+'[2]Total P&C'!$AZ$31)/1000/BP10 -> 0.057582111 | BR15: =-('[3]Total P&C'!$Q$29+'[3]Total P&C'!$X$29+'[3]Total P&C'!$AW$29+'[3]Total P&C'!$AZ$29)/1000/BR10 -> 0.081074199 | BS15: =-('[3]Total P&C'!$Q$30+'[3]Total P&C'!$X$30+'[3]Total P&C'!$AW$30+'[3]Total P&C'!$AZ$30)/1000/BS10 -> 0.08113309 | BT15: =-('[3]Total P&C'!$Q$31+'[3]Total P&C'!$X$31+'[3]Total P&C'!$AW$31+'[3]Total P&C'!$AZ$31)/1000/BT10 -> 0.074651351
D16: Others | J16: =-[1]Retail!$AT$29/1000/J10 -> 0.079006958 | K16: =-[1]Retail!$AT$30/1000/K10 -> 0.090567581 | L16: =-[1]Retail!$AT$31/1000/L10 -> #DIV/0! | N16: =-[1]SME!$AT$29/1000/N10 -> 0.024236296 | O16: =-[1]SME!$AT$30/1000/O10 -> 0.024904146 | P16: =-[1]SME!$AT$31/1000/P10 -> 0.022292102 | R16: =-[1]MidCorp!$AT$29/1000/R10 -> 0.025735987 | S16: =-[1]MidCorp!$AT$30/1000/S10 -> 0.075501677 | T16: =-[1]MidCorp!$AT$31/1000/T10 -> 0.091858398 | V16: =-[1]MGA!$AT$29/1000/V10 -> 0.016675129 | W16: =-[1]MGA!$AT$30/1000/W10 -> 0.020444108 | X16: =-[1]MGA!$AT$31/1000/X10 -> 0.025759851 | Z16: =-[1]Bancassurance!$AT$29/1000/Z10 -> 0 | AA16: =-[1]Bancassurance!$AT$30/1000/AA10 -> #DIV/0! | AB16: =-[1]Bancassurance!$AT$31/1000/AB10 -> #DIV/0! | AD16: =-[1]Specials!$AT$29/1000/AD10 -> -5.5344513 | AE16: =-[1]Specials!$AT$30/1000/AE10 -> -22.517775 | AF16: =-[1]Specials!$AT$31/1000/AF10 -> #DIV/0! | AH16: =-'[1]Total P&C'!$AT$29/1000/AH10 -> 0.020392799 | AI16: =-'[1]Total P&C'!$AT$30/1000/AI10 -> 0.051646049 | AJ16: =-'[1]Total P&C'!$AT$31/1000/AJ10 -> 0.064540746 | AN16: Others | AT16: =-[2]Retail!$AT$29/1000/AT10 -> 0.019070219 | AU16: =-[2]Retail!$AT$30/1000/AU10 -> 0.057271679 | AV16: =-[2]Retail!$AT$31/1000/AV10 -> 0.030124093 | AX16: =-[2]SME!$AT$29/1000/AX10 -> 0.015199834 | AY16: =-[2]SME!$AT$30/1000/AY10 -> 0.020465533 | AZ16: =-[2]SME!$AT$31/1000/AZ10 -> 0.016339088 | BB16: =-[2]MidCorp!$AT$29/1000/BB10 -> 0.079247301 | BC16: =-[2]MidCorp!$AT$30/1000/BC10 -> 0.064991725 | BD16: =-[2]MidCorp!$AT$31/1000/BD10 -> 0.11840346 | BJ16: =-[2]Specials!$AT$29/1000/BJ10 -> #DIV/0! | BK16: =-[2]Specials!$AT$30/1000/BK10 -> #DIV/0! | BL16: =-[2]Specials!$AT$31/1000/BL10 -> #DIV/0! | BN16: =-'[2]Total P&C'!$AT$29/1000/BN10 -> 0.037723241 | BO16: =-'[2]Total P&C'!$AT$30/1000/BO10 -> 0.054094097 | BP16: =-'[2]Total P&C'!$AT$31/1000/BP10 -> 0.054806661 | BR16: =-'[3]Total P&C'!$AT$29/1000/BR10 -> 0.023434515 | BS16: =-'[3]Total P&C'!$AT$30/1000/BS10 -> 0.052121506 | BT16: =-'[3]Total P&C'!$AT$31/1000/BT10 -> 0.062724167
D17: Discounting a.y. | J17: =-([1]Retail!$Z$29+[1]Retail!$AA$29+[1]Retail!$BB$29+[1]Retail!$BC$29)/1000/J10 -> -0.0099639839 | K17: =-([1]Retail!$Z$30+[1]Retail!$AA$30+[1]Retail!$BB$30+[1]Retail!$BC$30)/1000/K10 -> -0.082072747 | L17: =-([1]Retail!$Z$31+[1]Retail!$AA$31+[1]Retail!$BB$31+[1]Retail!$BC$31)/1000/L10 -> #DIV/0! | N17: =-([1]SME!$Z$29+[1]SME!$AA$29+[1]SME!$BB$29+[1]SME!$BC$29)/1000/N10 -> -0.037544493 | O17: =-([1]SME!$Z$30+[1]SME!$AA$30+[1]SME!$BB$30+[1]SME!$BC$30)/1000/O10 -> -0.02132255 | P17: =-([1]SME!$Z$31+[1]SME!$AA$31+[1]SME!$BB$31+[1]SME!$BC$31)/1000/P10 -> -0.022956172 | R17: =-([1]MidCorp!$Z$29+[1]MidCorp!$AA$29+[1]MidCorp!$BB$29+[1]MidCorp!$BC$29)/1000/R10 -> -0.048980363 | S17: =-([1]MidCorp!$Z$30+[1]MidCorp!$AA$30+[1]MidCorp!$BB$30+[1]MidCorp!$BC$30)/1000/S10 -> -0.03682943 | T17: =-([1]MidCorp!$Z$31+[1]MidCorp!$AA$31+[1]MidCorp!$BB$31+[1]MidCorp!$BC$31)/1000/T10 -> -0.024368918 | V17: =-([1]MGA!$Z$29+[1]MGA!$AA$29+[1]MGA!$BB$29+[1]MGA!$BC$29)/1000/V10 -> -0.030589031 | W17: =-([1]MGA!$Z$30+[1]MGA!$AA$30+[1]MGA!$BB$30+[1]MGA!$BC$30)/1000/W10 -> -0.033686976 | X17: =-([1]MGA!$Z$31+[1]MGA!$AA$31+[1]MGA!$BB$31+[1]MGA!$BC$31)/1000/X10 -> -0.027968701 | Z17: =-([1]Bancassurance!$Z$29+[1]Bancassurance!$AA$29+[1]Bancassurance!$BB$29+[1]Bancassurance!$BC$29)/1000/Z10 -> 0 | AA17: =-([1]Bancassurance!$Z$30+[1]Bancassurance!$AA$30+[1]Bancassurance!$BB$30+[1]Bancassurance!$BC$30)/1000/AA10 -> #DIV/0! | AB17: =-([1]Bancassurance!$Z$31+[1]Bancassurance!$AA$31+[1]Bancassurance!$BB$31+[1]Bancassurance!$BC$31)/1000/AB10 -> #DIV/0! | AD17: =-([1]Specials!$Z$29+[1]Specials!$AA$29+[1]Specials!$BB$29+[1]Specials!$BC$29)/1000/AD10 -> 0 | AE17: =-([1]Specials!$Z$30+[1]Specials!$AA$30+[1]Specials!$BB$30+[1]Specials!$BC$30)/1000/AE10 -> 0 | AF17: =-([1]Specials!$Z$31+[1]Specials!$AA$31+[1]Specials!$BB$31+[1]Specials!$BC$31)/1000/AF10 -> #DIV/0! | AH17: =-('[1]Total P&C'!$Z$29+'[1]Total P&C'!$AA$29+'[1]Total P&C'!$BB$29+'[1]Total P&C'!$BC$29)/1000/AH10 -> -0.042489475 | AI17: =-('[1]Total P&C'!$Z$30+'[1]Total P&C'!$AA$30+'[1]Total P&C'!$BB$30+'[1]Total P&C'!$BC$30)/1000/AI10 -> -0.034585864 | AJ17: =-('[1]Total P&C'!$Z$31+'[1]Total P&C'!$AA$31+'[1]Total P&C'!$BB$31+'[1]Total P&C'!$BC$31)/1000/AJ10 -> -0.025121451 | AN17: Discounting a.y. | AT17: =-([2]Retail!$Z$29+[2]Retail!$AA$29+[2]Retail!$BB$29+[2]Retail!$BC$29)/1000/AT10 -> -0.043734096 | AU17: =-([2]Retail!$Z$30+[2]Retail!$AA$30+[2]Retail!$BB$30+[2]Retail!$BC$30)/1000/AU10 -> -0.031585955 | AV17: =-([2]Retail!$Z$31+[2]Retail!$AA$31+[2]Retail!$BB$31+[2]Retail!$BC$31)/1000/AV10 -> -0.017551049 | AX17: =-([2]SME!$Z$29+[2]SME!$AA$29+[2]SME!$BB$29+[2]SME!$BC$29)/1000/AX10 -> -0.034793711 | AY17: =-([2]SME!$Z$30+[2]SME!$AA$30+[2]SME!$BB$30+[2]SME!$BC$30)/1000/AY10 -> -0.023938378 | AZ17: =-([2]SME!$Z$31+[2]SME!$AA$31+[2]SME!$BB$31+[2]SME!$BC$31)/1000/AZ10 -> -0.019477821 | BB17: =-([2]MidCorp!$Z$29+[2]MidCorp!$AA$29+[2]MidCorp!$BB$29+[2]MidCorp!$BC$29)/1000/BB10 -> -0.054958187 | BC17: =-([2]MidCorp!$Z$30+[2]MidCorp!$AA$30+[2]MidCorp!$BB$30+[2]MidCorp!$BC$30)/1000/BC10 -> -0.036296283 | BD17: =-([2]MidCorp!$Z$31+[2]MidCorp!$AA$31+[2]MidCorp!$BB$31+[2]MidCorp!$BC$31)/1000/BD10 -> -0.024573048 | BJ17: =-([2]Specials!$Z$29+[2]Specials!$AA$29+[2]Specials!$BB$29+[2]Specials!$BC$29)/1000/BJ10 -> #DIV/0! | BK17: =-([2]Specials!$Z$30+[2]Specials!$AA$30+[2]Specials!$BB$30+[2]Specials!$BC$30)/1000/BK10 -> #DIV/0! | BL17: =-([2]Specials!$Z$31+[2]Specials!$AA$31+[2]Specials!$BB$31+[2]Specials!$BC$31)/1000/BL10 -> #DIV/0! | BN17: =-('[2]Total P&C'!$Z$29+'[2]Total P&C'!$AA$29+'[2]Total P&C'!$BB$29+'[2]Total P&C'!$BC$29)/1000/BN10 -> -0.045881078 | BO17: =-('[2]Total P&C'!$Z$30+'[2]Total P&C'!$AA$30+'[2]Total P&C'!$BB$30+'[2]Total P&C'!$BC$30)/1000/BO10 -> -0.032013024 | BP17: =-('[2]Total P&C'!$Z$31+'[2]Total P&C'!$AA$31+'[2]Total P&C'!$BB$31+'[2]Total P&C'!$BC$31)/1000/BP10 -> -0.020011441 | BR17: =-('[3]Total P&C'!$Z$29+'[3]Total P&C'!$AA$29+'[3]Total P&C'!$BB$29+'[3]Total P&C'!$BC$29)/1000/BR10 -> -0.043084745 | BS17: =-('[3]Total P&C'!$Z$30+'[3]Total P&C'!$AA$30+'[3]Total P&C'!$BB$30+'[3]Total P&C'!$BC$30)/1000/BS10 -> -0.03408617 | BT17: =-('[3]Total P&C'!$Z$31+'[3]Total P&C'!$AA$31+'[3]Total P&C'!$BB$31+'[3]Total P&C'!$BC$31)/1000/BT10 -> -0.024167819
D18: Run-off + ReR | J18: =-SUM([1]Retail!$AC$29:$AI$29,[1]Retail!$BE$29:$BG$29)/1000/J10 -> 0.18391495 | K18: =-SUM([1]Retail!$AC$30:$AI$30,[1]Retail!$BE$30:$BG$30)/1000/K10 -> -1.4278633 | L18: =-SUM([1]Retail!$AC$31:$AI$31,[1]Retail!$BE$31:$BG$31)/1000/L10 -> #DIV/0! | N18: =-SUM([1]SME!$AC$29:$AI$29,[1]SME!$BE$29:$BG$29)/1000/N10 -> -0.033712429 | O18: =-SUM([1]SME!$AC$30:$AI$30,[1]SME!$BE$30:$BG$30)/1000/O10 -> 0.18815306 | P18: =-SUM([1]SME!$AC$31:$AI$31,[1]SME!$BE$31:$BG$31)/1000/P10 -> -0.0072292083 | R18: =-SUM([1]MidCorp!$AC$29:$AI$29,[1]MidCorp!$BE$29:$BG$29)/1000/R10 -> 0.085719765 | S18: =-SUM([1]MidCorp!$AC$30:$AI$30,[1]MidCorp!$BE$30:$BG$30)/1000/S10 -> 0.0023897793 | T18: =-SUM([1]MidCorp!$AC$31:$AI$31,[1]MidCorp!$BE$31:$BG$31)/1000/T10 -> -0.0051062173 | V18: =-SUM([1]MGA!$AC$29:$AI$29,[1]MGA!$BE$29:$BG$29)/1000/V10 -> -0.15943284 | W18: =-SUM([1]MGA!$AC$30:$AI$30,[1]MGA!$BE$30:$BG$30)/1000/W10 -> 0.0073111524 | X18: =-SUM([1]MGA!$AC$31:$AI$31,[1]MGA!$BE$31:$BG$31)/1000/X10 -> -0.023379002 | Z18: =-SUM([1]Bancassurance!$AC$29:$AI$29,[1]Bancassurance!$BE$29:$BG$29)/1000/Z10 -> 0 | AA18: =-SUM([1]Bancassurance!$AC$30:$AI$30,[1]Bancassurance!$BE$30:$BG$30)/1000/AA10 -> #DIV/0! | AB18: =-SUM([1]Bancassurance!$AC$31:$AI$31,[1]Bancassurance!$BE$31:$BG$31)/1000/AB10 -> #DIV/0! | AD18: =-SUM([1]Specials!$AC$29:$AI$29,[1]Specials!$BE$29:$BG$29)/1000/AD10 -> -2.1424295 | AE18: =-SUM([1]Specials!$AC$30:$AI$30,[1]Specials!$BE$30:$BG$30)/1000/AE10 -> -5.6895911 | AF18: =-SUM([1]Specials!$AC$31:$AI$31,[1]Specials!$BE$31:$BG$31)/1000/AF10 -> #DIV/0! | AH18: =-SUM('[1]Total P&C'!$AC$29:$AI$29,'[1]Total P&C'!$BE$29:$BG$29)/1000/AH10 -> 0.010742823 | AI18: =-SUM('[1]Total P&C'!$AC$30:$AI$30,'[1]Total P&C'!$BE$30:$BG$30)/1000/AI10 -> 0.0048085321 | AJ18: =-SUM('[1]Total P&C'!$AC$31:$AI$31,'[1]Total P&C'!$BE$31:$BG$31)/1000/AJ10 -> -0.014620934 | AN18: Run-off + ReR | AT18: =-SUM([2]Retail!$AC$29:$AI$29,[2]Retail!$BE$29:$BG$29)/1000/AT10 -> 0.47776292 | AU18: =-SUM([2]Retail!$AC$30:$AI$30,[2]Retail!$BE$30:$BG$30)/1000/AU10 -> -0.33584829 | AV18: =-SUM([2]Retail!$AC$31:$AI$31,[2]Retail!$BE$31:$BG$31)/1000/AV10 -> 0.0053656086 | AX18: =-SUM([2]SME!$AC$29:$AI$29,[2]SME!$BE$29:$BG$29)/1000/AX10 -> 0.46355565 | AY18: =-SUM([2]SME!$AC$30:$AI$30,[2]SME!$BE$30:$BG$30)/1000/AY10 -> 0.011924534 | AZ18: =-SUM([2]SME!$AC$31:$AI$31,[2]SME!$BE$31:$BG$31)/1000/AZ10 -> 0.034684462 | BB18: =-SUM([2]MidCorp!$AC$29:$AI$29,[2]MidCorp!$BE$29:$BG$29)/1000/BB10 -> 0.13410523 | BC18: =-SUM([2]MidCorp!$AC$30:$AI$30,[2]MidCorp!$BE$30:$BG$30)/1000/BC10 -> 0.33922916 | BD18: =-SUM([2]MidCorp!$AC$31:$AI$31,[2]MidCorp!$BE$31:$BG$31)/1000/BD10 -> 0.015801103 | BJ18: =-SUM([2]Specials!$AC$29:$AI$29,[2]Specials!$BE$29:$BG$29)/1000/BJ10 -> #DIV/0! | BK18: =-SUM([2]Specials!$AC$30:$AI$30,[2]Specials!$BE$30:$BG$30)/1000/BK10 -> #DIV/0! | BL18: =-SUM([2]Specials!$AC$31:$AI$31,[2]Specials!$BE$31:$BG$31)/1000/BL10 -> #DIV/0! | BN18: =-SUM('[2]Total P&C'!$AC$29:$AI$29,'[2]Total P&C'!$BE$29:$BG$29)/1000/BN10 -> 0.36535421 | BO18: =-SUM('[2]Total P&C'!$AC$30:$AI$30,'[2]Total P&C'!$BE$30:$BG$30)/1000/BO10 -> -0.043988128 | BP18: =-SUM('[2]Total P&C'!$AC$31:$AI$31,'[2]Total P&C'!$BE$31:$BG$31)/1000/BP10 -> 0.013371686 | BR18: =-SUM('[3]Total P&C'!$AC$29:$AI$29,'[3]Total P&C'!$BE$29:$BG$29)/1000/BR10 -> 0.072981689 | BS18: =-SUM('[3]Total P&C'!$AC$30:$AI$30,'[3]Total P&C'!$BE$30:$BG$30)/1000/BS10 -> -0.0046687058 | BT18: =-SUM('[3]Total P&C'!$AC$31:$AI$31,'[3]Total P&C'!$BE$31:$BG$31)/1000/BT10 -> -0.0093969411
D19: Discounting Run-off | J19: =-SUM([1]Retail!$AJ$29:$AK$29,[1]Retail!$BH$29:$BI$29)/1000/J10 -> 0.33452729 | K19: =-SUM([1]Retail!$AJ$30:$AK$30,[1]Retail!$BH$30:$BI$30)/1000/K10 -> 0.061155615 | L19: =-SUM([1]Retail!$AJ$31:$AK$31,[1]Retail!$BH$31:$BI$31)/1000/L10 -> #DIV/0! | N19: =-SUM([1]SME!$AJ$29:$AK$29,[1]SME!$BH$29:$BI$29)/1000/N10 -> -0.013082522 | O19: =-SUM([1]SME!$AJ$30:$AK$30,[1]SME!$BH$30:$BI$30)/1000/O10 -> -0.01810219 | P19: =-SUM([1]SME!$AJ$31:$AK$31,[1]SME!$BH$31:$BI$31)/1000/P10 -> 0 | R19: =-SUM([1]MidCorp!$AJ$29:$AK$29,[1]MidCorp!$BH$29:$BI$29)/1000/R10 -> -0.0074097296 | S19: =-SUM([1]MidCorp!$AJ$30:$AK$30,[1]MidCorp!$BH$30:$BI$30)/1000/S10 -> 0.018929945 | T19: =-SUM([1]MidCorp!$AJ$31:$AK$31,[1]MidCorp!$BH$31:$BI$31)/1000/T10 -> 0 | V19: =-SUM([1]MGA!$AJ$29:$AK$29,[1]MGA!$BH$29:$BI$29)/1000/V10 -> 0.12006639 | W19: =-SUM([1]MGA!$AJ$30:$AK$30,[1]MGA!$BH$30:$BI$30)/1000/W10 -> -0.084584214 | X19: =-SUM([1]MGA!$AJ$31:$AK$31,[1]MGA!$BH$31:$BI$31)/1000/X10 -> 0 | Z19: =-SUM([1]Bancassurance!$AJ$29:$AK$29,[1]Bancassurance!$BH$29:$BI$29)/1000/Z10 -> 0 | AA19: =-SUM([1]Bancassurance!$AJ$30:$AK$30,[1]Bancassurance!$BH$30:$BI$30)/1000/AA10 -> #DIV/0! | AB19: =-SUM([1]Bancassurance!$AJ$31:$AK$31,[1]Bancassurance!$BH$31:$BI$31)/1000/AB10 -> #DIV/0! | AD19: =-SUM([1]Specials!$AJ$29:$AK$29,[1]Specials!$BH$29:$BI$29)/1000/AD10 -> 0.46728918 | AE19: =-SUM([1]Specials!$AJ$30:$AK$30,[1]Specials!$BH$30:$BI$30)/1000/AE10 -> -1.9030783 | AF19: =-SUM([1]Specials!$AJ$31:$AK$31,[1]Specials!$BH$31:$BI$31)/1000/AF10 -> #DIV/0! | AH19: =-SUM('[1]Total P&C'!$AJ$29:$AK$29,'[1]Total P&C'!$BH$29:$BI$29)/1000/AH10 -> 0.027417426 | AI19: =-SUM('[1]Total P&C'!$AJ$30:$AK$30,'[1]Total P&C'!$BH$30:$BI$30)/1000/AI10 -> -0.0099536025 | AJ19: =-SUM('[1]Total P&C'!$AJ$31:$AK$31,'[1]Total P&C'!$BH$31:$BI$31)/1000/AJ10 -> 0 | AN19: Discounting Run-off | AT19: =-SUM([2]Retail!$AJ$29:$AK$29,[2]Retail!$BH$29:$BI$29)/1000/AT10 -> -0.60839864 | AU19: =-SUM([2]Retail!$AJ$30:$AK$30,[2]Retail!$BH$30:$BI$30)/1000/AU10 -> -0.035545513 | AV19: =-SUM([2]Retail!$AJ$31:$AK$31,[2]Retail!$BH$31:$BI$31)/1000/AV10 -> 0 | AX19: =-SUM([2]SME!$AJ$29:$AK$29,[2]SME!$BH$29:$BI$29)/1000/AX10 -> -0.57658296 | AY19: =-SUM([2]SME!$AJ$30:$AK$30,[2]SME!$BH$30:$BI$30)/1000/AY10 -> -0.051957115 | AZ19: =-SUM([2]SME!$AJ$31:$AK$31,[2]SME!$BH$31:$BI$31)/1000/AZ10 -> 0 | BB19: =-SUM([2]MidCorp!$AJ$29:$AK$29,[2]MidCorp!$BH$29:$BI$29)/1000/BB10 -> -0.29942834 | BC19: =-SUM([2]MidCorp!$AJ$30:$AK$30,[2]MidCorp!$BH$30:$BI$30)/1000/BC10 -> -0.0078827691 | BD19: =-SUM([2]MidCorp!$AJ$31:$AK$31,[2]MidCorp!$BH$31:$BI$31)/1000/BD10 -> 0 | BJ19: =-SUM([2]Specials!$AJ$29:$AK$29,[2]Specials!$BH$29:$BI$29)/1000/BJ10 -> #DIV/0! | BK19: =-SUM([2]Specials!$AJ$30:$AK$30,[2]Specials!$BH$30:$BI$30)/1000/BK10 -> #DIV/0! | BL19: =-SUM([2]Specials!$AJ$31:$AK$31,[2]Specials!$BH$31:$BI$31)/1000/BL10 -> #DIV/0! | BN19: =-SUM('[2]Total P&C'!$AJ$29:$AK$29,'[2]Total P&C'!$BH$29:$BI$29)/1000/BN10 -> -0.50424941 | BO19: =-SUM('[2]Total P&C'!$AJ$30:$AK$30,'[2]Total P&C'!$BH$30:$BI$30)/1000/BO10 -> -0.028484315 | BP19: =-SUM('[2]Total P&C'!$AJ$31:$AK$31,'[2]Total P&C'!$BH$31:$BI$31)/1000/BP10 -> 0 | BR19: =-SUM('[3]Total P&C'!$AJ$29:$AK$29,'[3]Total P&C'!$BH$29:$BI$29)/1000/BR10 -> -0.065896952 | BS19: =-SUM('[3]Total P&C'!$AJ$30:$AK$30,'[3]Total P&C'!$BH$30:$BI$30)/1000/BS10 -> -0.013552619 | BT19: =-SUM('[3]Total P&C'!$AJ$31:$AK$31,'[3]Total P&C'!$BH$31:$BI$31)/1000/BT10 -> 0
D20: Expense ratio + ReR | J20: =+J21+J22+J23 -> 0.34596359 | K20: =+K21+K22+K23 -> 0.54604699 | L20: =+L21+L22+L23 -> #DIV/0! | N20: =+N21+N22+N23 -> 0.27932474 | O20: =+O21+O22+O23 -> 0.28309188 | P20: =+P21+P22+P23 -> 0.28546747 | R20: =+R21+R22+R23 -> 0.19471149 | S20: =+S21+S22+S23 -> 0.19464322 | T20: =+T21+T22+T23 -> 0.22206511 | V20: =+V21+V22+V23 -> 0.32889405 | W20: =+W21+W22+W23 -> 0.3193248 | X20: =+X21+X22+X23 -> 0.32131948 | Z20: =+Z21+Z22+Z23 -> 0.15005275 | AA20: =+AA21+AA22+AA23 -> #DIV/0! | AB20: =+AB21+AB22+AB23 -> #DIV/0! | AD20: =+AD21+AD22+AD23 -> 0 | AE20: =+AE21+AE22+AE23 -> 0 | AF20: =+AF21+AF22+AF23 -> #DIV/0! | AH20: =+AH21+AH22+AH23 -> 0.23996895 | AI20: =+AI21+AI22+AI23 -> 0.24299903 | AJ20: =+AJ21+AJ22+AJ23 -> 0.25931126 | AN20: Expense ratio + ReR | AT20: =+AT21+AT22+AT23 -> 0.34480766 | AU20: =+AU21+AU22+AU23 -> 0.3324183 | AV20: =+AV21+AV22+AV23 -> 0.33667054 | AX20: =+AX21+AX22+AX23 -> 0.38725268 | AY20: =+AY21+AY22+AY23 -> 0.36184421 | AZ20: =+AZ21+AZ22+AZ23 -> 0.3898946 | BB20: =+BB21+BB22+BB23 -> 0.29501349 | BC20: =+BC21+BC22+BC23 -> 0.26254148 | BD20: =+BD21+BD22+BD23 -> 0.30697295 | BJ20: =+BJ21+BJ22+BJ23 -> #DIV/0! | BK20: =+BK21+BK22+BK23 -> #DIV/0! | BL20: =+BL21+BL22+BL23 -> #DIV/0! | BN20: =+BN21+BN22+BN23 -> 0.33573383 | BO20: =+BO21+BO22+BO23 -> 0.31265967 | BP20: =+BP21+BP22+BP23 -> 0.33635556 | BR20: =+BR21+BR22+BR23 -> 0.25677692 | BS20: =+BS21+BS22+BS23 -> 0.25652845 | BT20: =+BT21+BT22+BT23 -> 0.2736893
D21: Commission | J21: =-SUM([1]Retail!$AL$29:$AN$29,[1]Retail!$BJ$29)/1000/J10 -> 0.18252445 | K21: =-SUM([1]Retail!$AL$30:$AN$30,[1]Retail!$BJ$30)/1000/K10 -> 0.18659632 | L21: =-SUM([1]Retail!$AL$31:$AN$31,[1]Retail!$BJ$31)/1000/L10 -> #DIV/0! | N21: =-SUM([1]SME!$AL$29:$AN$29,[1]SME!$BJ$29)/1000/N10 -> 0.16297493 | O21: =-SUM([1]SME!$AL$30:$AN$30,[1]SME!$BJ$30)/1000/O10 -> 0.16191156 | P21: =-SUM([1]SME!$AL$31:$AN$31,[1]SME!$BJ$31)/1000/P10 -> 0.16158192 | R21: =-SUM([1]MidCorp!$AL$29:$AN$29,[1]MidCorp!$BJ$29)/1000/R10 -> 0.10118582 | S21: =-SUM([1]MidCorp!$AL$30:$AN$30,[1]MidCorp!$BJ$30)/1000/S10 -> 0.10371762 | T21: =-SUM([1]MidCorp!$AL$31:$AN$31,[1]MidCorp!$BJ$31)/1000/T10 -> 0.10477137 | V21: =-SUM([1]MGA!$AL$29:$AN$29,[1]MGA!$BJ$29)/1000/V10 -> 0.26900051 | W21: =-SUM([1]MGA!$AL$30:$AN$30,[1]MGA!$BJ$30)/1000/W10 -> 0.26088453 | X21: =-SUM([1]MGA!$AL$31:$AN$31,[1]MGA!$BJ$31)/1000/X10 -> 0.24877882 | Z21: =-SUM([1]Bancassurance!$AL$29:$AN$29,[1]Bancassurance!$BJ$29)/1000/Z10 -> 0.15005275 | AA21: =-SUM([1]Bancassurance!$AL$30:$AN$30,[1]Bancassurance!$BJ$30)/1000/AA10 -> #DIV/0! | AB21: =-SUM([1]Bancassurance!$AL$31:$AN$31,[1]Bancassurance!$BJ$31)/1000/AB10 -> #DIV/0! | AD21: =-SUM([1]Specials!$AL$29:$AN$29,[1]Specials!$BJ$29)/1000/AD10 -> 0 | AE21: =-SUM([1]Specials!$AL$30:$AN$30,[1]Specials!$BJ$30)/1000/AE10 -> 0 | AF21: =-SUM([1]Specials!$AL$31:$AN$31,[1]Specials!$BJ$31)/1000/AF10 -> #DIV/0! | AH21: =-SUM('[1]Total P&C'!$AL$29:$AN$29,'[1]Total P&C'!$BJ$29)/1000/AH10 -> 0.15077857 | AI21: =-SUM('[1]Total P&C'!$AL$30:$AN$30,'[1]Total P&C'!$BJ$30)/1000/AI10 -> 0.14997419 | AJ21: =-SUM('[1]Total P&C'!$AL$31:$AN$31,'[1]Total P&C'!$BJ$31)/1000/AJ10 -> 0.15089465 | AN21: Commission | AT21: =-SUM([2]Retail!$AL$29:$AN$29,[2]Retail!$BJ$29)/1000/AT10 -> 0.16486588 | AU21: =-SUM([2]Retail!$AL$30:$AN$30,[2]Retail!$BJ$30)/1000/AU10 -> 0.16431696 | AV21: =-SUM([2]Retail!$AL$31:$AN$31,[2]Retail!$BJ$31)/1000/AV10 -> 0.16622672 | AX21: =-SUM([2]SME!$AL$29:$AN$29,[2]SME!$BJ$29)/1000/AX10 -> 0.19736587 | AY21: =-SUM([2]SME!$AL$30:$AN$30,[2]SME!$BJ$30)/1000/AY10 -> 0.19240737 | AZ21: =-SUM([2]SME!$AL$31:$AN$31,[2]SME!$BJ$31)/1000/AZ10 -> 0.20630263 | BB21: =-SUM([2]MidCorp!$AL$29:$AN$29,[2]MidCorp!$BJ$29)/1000/BB10 -> 0.11308665 | BC21: =-SUM([2]MidCorp!$AL$30:$AN$30,[2]MidCorp!$BJ$30)/1000/BC10 -> 0.1228958 | BD21: =-SUM([2]MidCorp!$AL$31:$AN$31,[2]MidCorp!$BJ$31)/1000/BD10 -> 0.12047252 | BJ21: =-SUM([2]Specials!$AL$29:$AN$29,[2]Specials!$BJ$29)/1000/BJ10 -> #DIV/0! | BK21: =-SUM([2]Specials!$AL$30:$AN$30,[2]Specials!$BJ$30)/1000/BK10 -> #DIV/0! | BL21: =-SUM([2]Specials!$AL$31:$AN$31,[2]Specials!$BJ$31)/1000/BL10 -> #DIV/0! | BN21: =-SUM('[2]Total P&C'!$AL$29:$AN$29,'[2]Total P&C'!$BJ$29)/1000/BN10 -> 0.15354406 | BO21: =-SUM('[2]Total P&C'!$AL$30:$AN$30,'[2]Total P&C'!$BJ$30)/1000/BO10 -> 0.15430552 | BP21: =-SUM('[2]Total P&C'!$AL$31:$AN$31,'[2]Total P&C'!$BJ$31)/1000/BP10 -> 0.1588484 | BR21: =-SUM('[3]Total P&C'!$AL$29:$AN$29,'[3]Total P&C'!$BJ$29)/1000/BR10 -> 0.15126395 | BS21: =-SUM('[3]Total P&C'!$AL$30:$AN$30,'[3]Total P&C'!$BJ$30)/1000/BS10 -> 0.15081542 | BT21: =-SUM('[3]Total P&C'!$AL$31:$AN$31,'[3]Total P&C'!$BJ$31)/1000/BT10 -> 0.15237898
D22: Acquisition | J22: =-SUM([1]Retail!$AO$29:$AP$29)/1000/J10 -> 0.005387357 | K22: =-SUM([1]Retail!$AO$30:$AP$30)/1000/K10 -> 0.056090318 | L22: =-SUM([1]Retail!$AO$31:$AP$31)/1000/L10 -> #DIV/0! | N22: =-SUM([1]SME!$AO$29:$AP$29)/1000/N10 -> 0.051243221 | O22: =-SUM([1]SME!$AO$30:$AP$30)/1000/O10 -> 0.059864908 | P22: =-SUM([1]SME!$AO$31:$AP$31)/1000/P10 -> 0.049226248 | R22: =-SUM([1]MidCorp!$AO$29:$AP$29)/1000/R10 -> 0.017664929 | S22: =-SUM([1]MidCorp!$AO$30:$AP$30)/1000/S10 -> 0.015764922 | T22: =-SUM([1]MidCorp!$AO$31:$AP$31)/1000/T10 -> 0.019997913 | V22: =-SUM([1]MGA!$AO$29:$AP$29)/1000/V10 -> 0.01907292 | W22: =-SUM([1]MGA!$AO$30:$AP$30)/1000/W10 -> 0.014468002 | X22: =-SUM([1]MGA!$AO$31:$AP$31)/1000/X10 -> 0.022731927 | Z22: =-SUM([1]Bancassurance!$AO$29:$AP$29)/1000/Z10 -> 0 | AA22: =-SUM([1]Bancassurance!$AO$30:$AP$30)/1000/AA10 -> #DIV/0! | AB22: =-SUM([1]Bancassurance!$AO$31:$AP$31)/1000/AB10 -> #DIV/0! | AD22: =-SUM([1]Specials!$AO$29:$AP$29)/1000/AD10 -> 0 | AE22: =-SUM([1]Specials!$AO$30:$AP$30)/1000/AE10 -> 0 | AF22: =-SUM([1]Specials!$AO$31:$AP$31)/1000/AF10 -> #DIV/0! | AH22: =-SUM('[1]Total P&C'!$AO$29:$AP$29)/1000/AH10 -> 0.022199133 | AI22: =-SUM('[1]Total P&C'!$AO$30:$AP$30)/1000/AI10 -> 0.023004984 | AJ22: =-SUM('[1]Total P&C'!$AO$31:$AP$31)/1000/AJ10 -> 0.024920702 | AN22: Acquisition | AT22: =-SUM([2]Retail!$AO$29:$AP$29)/1000/AT10 -> 0.099420012 | AU22: =-SUM([2]Retail!$AO$30:$AP$30)/1000/AU10 -> 0.093725473 | AV22: =-SUM([2]Retail!$AO$31:$AP$31)/1000/AV10 -> 0.092248224 | AX22: =-SUM([2]SME!$AO$29:$AP$29)/1000/AX10 -> 0.092953494 | AY22: =-SUM([2]SME!$AO$30:$AP$30)/1000/AY10 -> 0.083746917 | AZ22: =-SUM([2]SME!$AO$31:$AP$31)/1000/AZ10 -> 0.078496456 | BB22: =-SUM([2]MidCorp!$AO$29:$AP$29)/1000/BB10 -> 0.077122287 | BC22: =-SUM([2]MidCorp!$AO$30:$AP$30)/1000/BC10 -> 0.054461113 | BD22: =-SUM([2]MidCorp!$AO$31:$AP$31)/1000/BD10 -> 0.071038799 | BJ22: =-SUM([2]Specials!$AO$29:$AP$29)/1000/BJ10 -> #DIV/0! | BK22: =-SUM([2]Specials!$AO$30:$AP$30)/1000/BK10 -> #DIV/0! | BL22: =-SUM([2]Specials!$AO$31:$AP$31)/1000/BL10 -> #DIV/0! | BN22: =-SUM('[2]Total P&C'!$AO$29:$AP$29)/1000/BN10 -> 0.091227796 | BO22: =-SUM('[2]Total P&C'!$AO$30:$AP$30)/1000/BO10 -> 0.07838737 | BP22: =-SUM('[2]Total P&C'!$AO$31:$AP$31)/1000/BP10 -> 0.083512642 | BR22: =-SUM('[3]Total P&C'!$AO$29:$AP$29)/1000/BR10 -> 0.034314553 | BS22: =-SUM('[3]Total P&C'!$AO$30:$AP$30)/1000/BS10 -> 0.033761295 | BT22: =-SUM('[3]Total P&C'!$AO$31:$AP$31)/1000/BT10 -> 0.035855152
D23: Administration | J23: =-SUM([1]Retail!$AQ$29:$AR$29)/1000/J10 -> 0.15805178 | K23: =-SUM([1]Retail!$AQ$30:$AR$30)/1000/K10 -> 0.30336035 | L23: =-SUM([1]Retail!$AQ$31:$AR$31)/1000/L10 -> #DIV/0! | N23: =-SUM([1]SME!$AQ$29:$AR$29)/1000/N10 -> 0.065106588 | O23: =-SUM([1]SME!$AQ$30:$AR$30)/1000/O10 -> 0.061315412 | P23: =-SUM([1]SME!$AQ$31:$AR$31)/1000/P10 -> 0.074659305 | R23: =-SUM([1]MidCorp!$AQ$29:$AR$29)/1000/R10 -> 0.075860747 | S23: =-SUM([1]MidCorp!$AQ$30:$AR$30)/1000/S10 -> 0.075160677 | T23: =-SUM([1]MidCorp!$AQ$31:$AR$31)/1000/T10 -> 0.09729582 | V23: =-SUM([1]MGA!$AQ$29:$AR$29)/1000/V10 -> 0.040820616 | W23: =-SUM([1]MGA!$AQ$30:$AR$30)/1000/W10 -> 0.043972272 | X23: =-SUM([1]MGA!$AQ$31:$AR$31)/1000/X10 -> 0.049808737 | Z23: =-SUM([1]Bancassurance!$AQ$29:$AR$29)/1000/Z10 -> 0 | AA23: =-SUM([1]Bancassurance!$AQ$30:$AR$30)/1000/AA10 -> #DIV/0! | AB23: =-SUM([1]Bancassurance!$AQ$31:$AR$31)/1000/AB10 -> #DIV/0! | AD23: =-SUM([1]Specials!$AQ$29:$AR$29)/1000/AD10 -> 0 | AE23: =-SUM([1]Specials!$AQ$30:$AR$30)/1000/AE10 -> 0 | AF23: =-SUM([1]Specials!$AQ$31:$AR$31)/1000/AF10 -> #DIV/0! | AH23: =-SUM('[1]Total P&C'!$AQ$29:$AR$29)/1000/AH10 -> 0.066991245 | AI23: =-SUM('[1]Total P&C'!$AQ$30:$AR$30)/1000/AI10 -> 0.070019853 | AJ23: =-SUM('[1]Total P&C'!$AQ$31:$AR$31)/1000/AJ10 -> 0.083495914 | AN23: Administration | AT23: =-SUM([2]Retail!$AQ$29:$AR$29)/1000/AT10 -> 0.080521773 | AU23: =-SUM([2]Retail!$AQ$30:$AR$30)/1000/AU10 -> 0.074375873 | AV23: =-SUM([2]Retail!$AQ$31:$AR$31)/1000/AV10 -> 0.078195589 | AX23: =-SUM([2]SME!$AQ$29:$AR$29)/1000/AX10 -> 0.096933315 | AY23: =-SUM([2]SME!$AQ$30:$AR$30)/1000/AY10 -> 0.085689923 | AZ23: =-SUM([2]SME!$AQ$31:$AR$31)/1000/AZ10 -> 0.10509551 | BB23: =-SUM([2]MidCorp!$AQ$29:$AR$29)/1000/BB10 -> 0.10480456 | BC23: =-SUM([2]MidCorp!$AQ$30:$AR$30)/1000/BC10 -> 0.085184561 | BD23: =-SUM([2]MidCorp!$AQ$31:$AR$31)/1000/BD10 -> 0.11546163 | BJ23: =-SUM([2]Specials!$AQ$29:$AR$29)/1000/BJ10 -> #DIV/0! | BK23: =-SUM([2]Specials!$AQ$30:$AR$30)/1000/BK10 -> #DIV/0! | BL23: =-SUM([2]Specials!$AQ$31:$AR$31)/1000/BL10 -> #DIV/0! | BN23: =-SUM('[2]Total P&C'!$AQ$29:$AR$29)/1000/BN10 -> 0.090961981 | BO23: =-SUM('[2]Total P&C'!$AQ$30:$AR$30)/1000/BO10 -> 0.079966772 | BP23: =-SUM('[2]Total P&C'!$AQ$31:$AR$31)/1000/BP10 -> 0.093994511 | BR23: =-SUM('[3]Total P&C'!$AQ$29:$AR$29)/1000/BR10 -> 0.071198418 | BS23: =-SUM('[3]Total P&C'!$AQ$30:$AR$30)/1000/BS10 -> 0.071951733 | BT23: =-SUM('[3]Total P&C'!$AQ$31:$AR$31)/1000/BT10 -> 0.085455166
D24: Insurance Service Result | J24: =+[1]Retail!$BK$29/1000 -> 0.00806825 | K24: =+[1]Retail!$BK$30/1000 -> 0.56455387 | L24: =+[1]Retail!$BK$31/1000 -> 0.16401228 | N24: =+[1]SME!$BK$29/1000 -> 1.4282163 | O24: =+[1]SME!$BK$30/1000 -> -0.04587727 | P24: =+[1]SME!$BK$31/1000 -> 1.3058696 | R24: =+[1]MidCorp!$BK$29/1000 -> 0.74669515 | S24: =+[1]MidCorp!$BK$30/1000 -> 4.6789722 | T24: =+[1]MidCorp!$BK$31/1000 -> 2.3729878 | V24: =+[1]MGA!$BK$29/1000 -> 0.48738132 | W24: =+[1]MGA!$BK$30/1000 -> 1.9363633 | X24: =+[1]MGA!$BK$31/1000 -> 1.2019884 | Z24: =+[1]Bancassurance!$BK$29/1000 -> 0.03735553 | AA24: =+[1]Bancassurance!$BK$30/1000 -> -0.02490468 | AB24: =+[1]Bancassurance!$BK$31/1000 -> 0 | AD24: =+[1]Specials!$BK$29/1000 -> 0.63191197 | AE24: =+[1]Specials!$BK$30/1000 -> 0.58412767 | AF24: =+[1]Specials!$BK$31/1000 -> 0 | AH24: =+'[1]Total P&C'!$BK$29/1000 -> 3.3396285 | AI24: =+'[1]Total P&C'!$BK$30/1000 -> 7.6932351 | AJ24: =+'[1]Total P&C'!$BK$31/1000 -> 5.0448581 | AN24: Insurance Service Result | AT24: =+[2]Retail!$BK$29/1000 -> 1.3177537 | AU24: =+[2]Retail!$BK$30/1000 -> 3.2774154 | AV24: =+[2]Retail!$BK$31/1000 -> 0.2933166 | AX24: =+[2]SME!$BK$29/1000 -> -0.41201179 | AY24: =+[2]SME!$BK$30/1000 -> 0.36880338 | AZ24: =+[2]SME!$BK$31/1000 -> -0.54393185 | BB24: =+[2]MidCorp!$BK$29/1000 -> -1.1400242 | BC24: =+[2]MidCorp!$BK$30/1000 -> -4.5955594 | BD24: =+[2]MidCorp!$BK$31/1000 -> -1.3855469 | BJ24: =+[2]Specials!$BK$29/1000 -> 0 | BK24: =+[2]Specials!$BK$30/1000 -> 0 | BL24: =+[2]Specials!$BK$31/1000 -> 0 | BN24: =+'[2]Total P&C'!$BK$29/1000 -> -0.23428225 | BO24: =+'[2]Total P&C'!$BK$30/1000 -> -0.94934071 | BP24: =+'[2]Total P&C'!$BK$31/1000 -> -1.6361621 | BR24: =+'[3]Total P&C'!$BK$29/1000 -> 3.1053463 | BS24: =+'[3]Total P&C'!$BK$30/1000 -> 6.7438944 | BT24: =+'[3]Total P&C'!$BK$31/1000 -> 3.4086959
B26: MTPL | D26: GWP | J26: =+[1]Retail!$C$21/1000 -> 0.94467744 | K26: =+[1]Retail!$C$22/1000 -> 1.201728 | L26: =+[1]Retail!$C$23/1000 -> 0 | N26: =+[1]SME!$C$21/1000 -> 11.340722 | O26: =+[1]SME!$C$22/1000 -> 12.046397 | P26: =+[1]SME!$C$23/1000 -> 12.27762 | R26: =+[1]MidCorp!$C$21/1000 -> 54.983343 | S26: =+[1]MidCorp!$C$22/1000 -> 49.40399 | T26: =+[1]MidCorp!$C$23/1000 -> 49.38687 | V26: =+[1]MGA!$C$21/1000 -> 18.095317 | W26: =+[1]MGA!$C$22/1000 -> 16.027855 | X26: =+[1]MGA!$C$23/1000 -> 16.48508 | Z26: =+[1]Bancassurance!$C$21/1000 -> 0 | AA26: =+[1]Bancassurance!$C$22/1000 -> 0 | AB26: =+[1]Bancassurance!$C$23/1000 -> 0 | AD26: =+[1]Specials!$C$21/1000 -> 0.19433375 | AE26: =+[1]Specials!$C$22/1000 -> 0.12200984 | AF26: =+[1]Specials!$C$23/1000 -> 0 | AH26: =+'[1]Total P&C'!$C$21/1000 -> 85.558393 | AI26: =+'[1]Total P&C'!$C$22/1000 -> 78.80198 | AJ26: =+'[1]Total P&C'!$C$23/1000 -> 78.14957 | AL26: MTPL | AN26: GWP | AT26: =+[2]Retail!$C$21/1000 -> 7.7727622 | AU26: =+[2]Retail!$C$22/1000 -> 7.9758582 | AV26: =+[2]Retail!$C$23/1000 -> 9.0071362 | AX26: =+[2]SME!$C$21/1000 -> 2.2108949 | AY26: =+[2]SME!$C$22/1000 -> 2.3550842 | AZ26: =+[2]SME!$C$23/1000 -> 2.4117941 | BB26: =+[2]MidCorp!$C$21/1000 -> 6.3104131 | BC26: =+[2]MidCorp!$C$22/1000 -> 7.262468 | BD26: =+[2]MidCorp!$C$23/1000 -> 6.4797079 | BJ26: =+[2]Specials!$C$21/1000 -> 0 | BK26: =+[2]Specials!$C$22/1000 -> 0 | BL26: =+[2]Specials!$C$23/1000 -> 0 | BN26: =+'[2]Total P&C'!$C$21/1000 -> 16.29407 | BO26: =+'[2]Total P&C'!$C$22/1000 -> 17.59341 | BP26: =+'[2]Total P&C'!$C$23/1000 -> 17.898638 | BR26: =+'[3]Total P&C'!$C$21/1000 -> 101.85246 | BS26: =+'[3]Total P&C'!$C$22/1000 -> 96.39539 | BT26: =+'[3]Total P&C'!$C$23/1000 -> 96.048208
D27: Insurance Service Revenue | J27: =+[1]Retail!$N$21/1000 -> 0.95931627 | K27: =+[1]Retail!$N$22/1000 -> 1.1711001 | L27: =+[1]Retail!$N$23/1000 -> 0 | N27: =+[1]SME!$N$21/1000 -> 7.2882262 | O27: =+[1]SME!$N$22/1000 -> 7.7367101 | P27: =+[1]SME!$N$23/1000 -> 7.596553 | R27: =+[1]MidCorp!$N$21/1000 -> 43.5161 | S27: =+[1]MidCorp!$N$22/1000 -> 37.623425 | T27: =+[1]MidCorp!$N$23/1000 -> 38.709298 | V27: =+[1]MGA!$N$21/1000 -> 15.471581 | W27: =+[1]MGA!$N$22/1000 -> 13.696609 | X27: =+[1]MGA!$N$23/1000 -> 15.074523 | Z27: =+[1]Bancassurance!$N$21/1000 -> 0 | AA27: =+[1]Bancassurance!$N$22/1000 -> 0 | AB27: =+[1]Bancassurance!$N$23/1000 -> 0 | AD27: =+[1]Specials!$N$21/1000 -> 0.06909593 | AE27: =+[1]Specials!$N$22/1000 -> 0.01482135 | AF27: =+[1]Specials!$N$23/1000 -> 0 | AH27: =+'[1]Total P&C'!$N$21/1000 -> 67.30432 | AI27: =+'[1]Total P&C'!$N$22/1000 -> 60.242665 | AJ27: =+'[1]Total P&C'!$N$23/1000 -> 61.380375 | AN27: Insurance Service Revenue | AT27: =+[2]Retail!$N$21/1000 -> 7.5916697 | AU27: =+[2]Retail!$N$22/1000 -> 7.6689383 | AV27: =+[2]Retail!$N$23/1000 -> 8.4032179 | AX27: =+[2]SME!$N$21/1000 -> 1.8608463 | AY27: =+[2]SME!$N$22/1000 -> 1.9818039 | AZ27: =+[2]SME!$N$23/1000 -> 1.9861192 | BB27: =+[2]MidCorp!$N$21/1000 -> 4.2822112 | BC27: =+[2]MidCorp!$N$22/1000 -> 4.6941807 | BD27: =+[2]MidCorp!$N$23/1000 -> 4.131662 | BJ27: =+[2]Specials!$N$21/1000 -> 0 | BK27: =+[2]Specials!$N$22/1000 -> 0 | BL27: =+[2]Specials!$N$23/1000 -> 0 | BN27: =+'[2]Total P&C'!$N$21/1000 -> 13.734727 | BO27: =+'[2]Total P&C'!$N$22/1000 -> 14.344923 | BP27: =+'[2]Total P&C'!$N$23/1000 -> 14.520999 | BR27: =+'[3]Total P&C'!$N$21/1000 -> 81.039047 | BS27: =+'[3]Total P&C'!$N$22/1000 -> 74.587588 | BT27: =+'[3]Total P&C'!$N$23/1000 -> 75.901374
D28: CoR | J28: =+J29+J34+J35+J36+J37 -> 1.0172878 | K28: =+K29+K34+K35+K36+K37 -> 0.29341385 | L28: =+L29+L34+L35+L36+L37 -> #DIV/0! | N28: =+N29+N34+N35+N36+N37 -> 1.0101708 | O28: =+O29+O34+O35+O36+O37 -> 1.2646582 | P28: =+P29+P34+P35+P36+P37 -> 1.0941282 | R28: =+R29+R34+R35+R36+R37 -> 1.004745 | S28: =+S29+S34+S35+S36+S37 -> 0.97488672 | T28: =+T29+T34+T35+T36+T37 -> 0.99605638 | V28: =+V29+V34+V35+V36+V37 -> 1.2195132 | W28: =+W29+W34+W35+W36+W37 -> 0.91902832 | X28: =+X29+X34+X35+X36+X37 -> 1.0358868 | Z28: =+Z29+Z34+Z35+Z36+Z37 -> #DIV/0! | AA28: =+AA29+AA34+AA35+AA36+AA37 -> #DIV/0! | AB28: =+AB29+AB34+AB35+AB36+AB37 -> #DIV/0! | AD28: =+AD29+AD34+AD35+AD36+AD37 -> -6.1644669 | AE28: =+AE29+AE34+AE35+AE36+AE37 -> -30.384716 | AF28: =+AF29+AF34+AF35+AF36+AF37 -> #DIV/0! | AH28: =+AH29+AH34+AH35+AH36+AH37 -> 1.0475211 | AI28: =+AI29+AI34+AI35+AI36+AI37 -> 0.97864477 | AJ28: =+AJ29+AJ34+AJ35+AJ36+AJ37 -> 1.0128569 | AN28: CoR | AT28: =+AT29+AT34+AT35+AT36+AT37 -> 0.79181439 | AU28: =+AU29+AU34+AU35+AU36+AU37 -> 0.51016483 | AV28: =+AV29+AV34+AV35+AV36+AV37 -> 0.89191473 | AX28: =+AX29+AX34+AX35+AX36+AX37 -> 0.97580865 | AY28: =+AY29+AY34+AY35+AY36+AY37 -> 0.90635547 | AZ28: =+AZ29+AZ34+AZ35+AZ36+AZ37 -> 1.2388799 | BB28: =+BB29+BB34+BB35+BB36+BB37 -> 1.4196736 | BC28: =+BC29+BC34+BC35+BC36+BC37 -> 1.9442037 | BD28: =+BD29+BD34+BD35+BD36+BD37 -> 1.3347551 | BJ28: =+BJ29+BJ34+BJ35+BJ36+BJ37 -> #DIV/0! | BK28: =+BK29+BK34+BK35+BK36+BK37 -> #DIV/0! | BL28: =+BL29+BL34+BL35+BL36+BL37 -> #DIV/0! | BN28: =+BN29+BN34+BN35+BN36+BN37 -> 1.0124967 | BO28: =+BO29+BO34+BO35+BO36+BO37 -> 1.0341697 | BP28: =+BP29+BP34+BP35+BP36+BP37 -> 1.0653726 | BR28: =+BR29+BR34+BR35+BR36+BR37 -> 1.0415851 | BS28: =+BS29+BS34+BS35+BS36+BS37 -> 0.9893235 | BT28: =+BT29+BT34+BT35+BT36+BT37 -> 1.0229039
D29: L.R + ReR AY | J29: =+J30+J31+J32+J33 -> 0.16340121 | K29: =+K30+K31+K32+K33 -> 2.1728887 | L29: =+L30+L31+L32+L33 -> #DIV/0! | N29: =+N30+N31+N32+N33 -> 1.0509415 | O29: =+O30+O31+O32+O33 -> 0.68421973 | P29: =+P30+P31+P32+P33 -> 0.85941693 | R29: =+R30+R31+R32+R33 -> 0.87293392 | S29: =+S30+S31+S32+S33 -> 0.8318025 | T29: =+T30+T31+T32+T33 -> 0.86144793 | V29: =+V30+V31+V32+V33 -> 0.80742451 | W29: =+W30+W31+W32+W33 -> 0.77517821 | X29: =+X30+X31+X32+X33 -> 0.7849024 | Z29: =+Z30+Z31+Z32+Z33 -> #DIV/0! | AA29: =+AA30+AA31+AA32+AA33 -> #DIV/0! | AB29: =+AB30+AB31+AB32+AB33 -> #DIV/0! | AD29: =+AD30+AD31+AD32+AD33 -> -4.2983718 | AE29: =+AE30+AE31+AE32+AE33 -> -20.761469 | AF29: =+AF30+AF31+AF32+AF33 -> #DIV/0! | AH29: =+AH30+AH31+AH32+AH33 -> 0.86172873 | AI29: =+AI30+AI31+AI32+AI33 -> 0.82073292 | AJ29: =+AJ30+AJ31+AJ32+AJ33 -> 0.84334852 | AN29: L.R + ReR AY | AT29: =+AT30+AT31+AT32+AT33 -> 0.7051865 | AU29: =+AU30+AU31+AU32+AU33 -> 0.76676323 | AV29: =+AV30+AV31+AV32+AV33 -> 0.58793957 | AX29: =+AX30+AX31+AX32+AX33 -> 0.84503976 | AY29: =+AY30+AY31+AY32+AY33 -> 0.48836125 | AZ29: =+AZ30+AZ31+AZ32+AZ33 -> 0.79396338 | BB29: =+BB30+BB31+BB32+BB33 -> 1.5365526 | BC29: =+BC30+BC31+BC32+BC33 -> 1.2142868 | BD29: =+BD30+BD31+BD32+BD33 -> 1.0760238 | BJ29: =+BJ30+BJ31+BJ32+BJ33 -> #DIV/0! | BK29: =+BK30+BK31+BK32+BK33 -> #DIV/0! | BL29: =+BL30+BL31+BL32+BL33 -> #DIV/0! | BN29: =+BN30+BN31+BN32+BN33 -> 0.98333769 | BO29: =+BO30+BO31+BO32+BO33 -> 0.87474698 | BP29: =+BP30+BP31+BP32+BP33 -> 0.75499329 | BR29: =+BR30+BR31+BR32+BR33 -> 0.88233936 | BS29: =+BS30+BS31+BS32+BS33 -> 0.83112108 | BT29: =+BT30+BT31+BT32+BT33 -> 0.82644493
